Workbook

Sheet Demographic-Economic
B1: Region 1 | C1: Region 2 | D1: Region 3 | E1: Region 4 | F1: Region 5 | G1: Region 6
A2: Census, July 1, 2021 | B2: 6406008 | C2: 4386948 | D2: 5019684 | E2: 995544 | F2: 1257096 | G2: 313836
A3: Census, July 1, 2020 | B3: 6306408 | C3: 4212348 | D3: 4993764 | E3: 1010676 | F3: 1266672 | G3: 307884
A4: Census, July 1, 2019 | C4: 3231492 | D4: 4614048 | E4: 1110012 | F4: 1289472 | G4: 323820
A5: Percent over age 18 | B5: 0.772 | C5: 0.827 | D5: 0.785 | E5: 0.781 | F5: 0.76 | G5: 0.827
A6: Percent age 65 and older | B6: 0.165 | C6: 0.261 | D6: 0.137 | E6: 0.209 | F6: 0.172 | G6: 0.2
A7: Housing Units | B7: 2791896 | C7: 2523732 | D7: 2212536 | E7: 496548 | F7: 566592 | G7: 135480
A8: Owner-Occupied Housing Units | B8: 1904073 | C8: 1862514 | D8: 1323096 | E8: 333680 | F8: 365451 | G8: 102693
A9: Median Value of Owner-Occupied Housing Units | B9: Ꝕ 260,765 | C9: Ꝕ 248,083 | D9: Ꝕ 221,267 | E9: Ꝕ 121,135 | F9: Ꝕ 158,255 | G9: Ꝕ 175,164
A10: Median Monthly Homeowner Housing Costs | B10: Ꝕ 1,726 | C10: Ꝕ 1,644 | D10: Ꝕ 1,731 | E10: Ꝕ 1,474 | F10: Ꝕ 1,438 | G10: Ꝕ 1,486
A11: Median Rent | B11: Ꝕ 1,260 | C11: Ꝕ 1,287 | D11: Ꝕ 1,318 | E11: Ꝕ 923 | F11: Ꝕ 1,068 | G11: Ꝕ 882
A12: Building Permits, 2021 | B12: 95568 | C12: 83640 | D12: 39156 | E12: 1080 | F12: 4656 | G12: 2328
A13: Labor Force (percent over age 16 and older), 2016-2020 | B13: 0.648 | C13: 0.553 | D13: 0.627 | E13: 0.549 | F13: 0.557 | G13: 0.51
A14: Total accommodation and food services sales, 2017 (Ꝕ1,000) | B14: 22342094 | C14: 36406400 | D14: 17508375 | E14: 2774258 | F14: 2611585 | G14: 151132
A15: Total health care and social assistance receipts/revenue, 2017 (Ꝕ1,000) | B15: 51556220 | C15: 26864638 | D15: 70145543 | E15: 6658061 | F15: 9541905 | G15: 697773
A16: Total transportation and warehousing receipts/revenue, 2017 (Ꝕ1,000) | B16: 13500228 | C16: 2862506 | D16: 3929251 | E16: 2234577 | F16: 2307892 | G16: =SUM(B16:F16)*(1+'Inflation-Interest'!B58)*(1+'Inflation-Interest'!B59)*(1+'Inflation-Interest'!B60)*('Demographic-Economic'!G29/SUM('Demographic-Economic'!B29:F29)) -> 199078.17
A17: Total retail sales, 2017 (Ꝕ1,000) | B17: 120644546 | C17: 104661514 | D17: 86911348 | E17: 16147988 | F17: 17600539 | G17: 2241932
A18: Total retail sales per capita, 2017 | B18: Ꝕ 19,811 | C18: Ꝕ 26,171 | D18: Ꝕ 17,558 | E18: Ꝕ 15,350 | F18: Ꝕ 13,758 | G18: Ꝕ 6,959
A19: Households, 2016-2020 | B19: 2376180 | C19: 1634628 | D19: 1865736 | E19: 403548 | F19: 500448 | G19: 110052
A20: Persons per Household, 2016-2020 | B20: 2.55 | C20: 2.49 | D20: 2.47 | E20: 2.5 | F20: 2.5 | G20: 2.65
A21: Median Household Income | B21: Ꝕ 82,459 | C21: Ꝕ 68,123 | D21: Ꝕ 71,916 | E21: Ꝕ 48,615 | F21: Ꝕ 61,518 | G21: Ꝕ 69,340
A22: Prior Year Per Capita Income | B22: Ꝕ 45,482 | C22: Ꝕ 38,381 | D22: Ꝕ 40,937 | E22: Ꝕ 28,186 | F22: Ꝕ 32,418 | G22: Ꝕ 35,948
A23: Persons in poverty, percent | B23: 0.121 | C23: 0.128 | D23: 0.16 | E23: 0.191 | F23: 0.205 | G23: 0.168
A24: Total Number of Employers, 2020 | B24: 170172 | C24: 113688 | D24: 110220 | E24: 18924 | F24: 21132 | G24: 3888
A25: Total Employment, 2020 | B25: 2990424 | C25: 1412112 | D25: 1941528 | E25: 284904 | F25: 388428 | G25: 65676
A26: Total Annual Payroll (Ꝕ1,000) | B26: 186551503 | C26: 60187999 | D26: 116972082 | E26: 14470878 | F26: 20694659 | G26: 2989576
A27: Population per hectare | B27: 2.58 | C27: 1.19 | D27: 2.12 | E27: 0.29 | F27: 0.61 | G27: 0.19
A28: Land area in hectares | B28: 2442659 | C28: 3522311 | D28: 2353615 | E28: 3438613 | F28: 2067059 | G28: 1556199
A29: GDP, 2020 (Ꝕ1,000 ) | B29: 531771287 | C29: 222153795 | D29: 417708522 | E29: 45815957 | F29: 69643447 | G29: 9845914
A30: GDP, 2019 (Ꝕ1,000 ) | B30: 534828123 | C30: 223457321 | D30: 414066160 | E30: 46354925 | F30: 68360180 | G30: 9766147
A31: Temporary housing cost with disaster (per person per month) | B31: 1920 | C31: 1829 | D31: 1925 | E31: 1639 | F31: 1599 | G31: 1653 | H31: Estimated average property value distribution
A32: Property Value distribution <Ꝕ50K | B32: 0.043 | C32: 0.0633 | D32: 0.0356 | E32: 0.1882 | F32: 0.0996 | G32: 0.0759 | H32: =50000 -> 50000
A33: Property Value distribution Ꝕ50K-Ꝕ99K | B33: 0.0459 | C33: 0.0537 | D33: 0.0623 | E33: 0.1888 | F33: 0.1397 | G33: 0.1579 | H33: =(50000+99000)/2 -> 74500
A34: Property Value distribution Ꝕ100K-Ꝕ149K | B34: 0.0695 | C34: 0.0693 | D34: 0.1123 | E34: 0.1578 | F34: 0.1891 | G34: 0.1336 | H34: =(100000+149000)/2 -> 124500
A35: Property Value distribution Ꝕ150K-Ꝕ199K | B35: 0.1604 | C35: 0.1531 | D35: 0.2161 | E35: 0.1726 | F35: 0.1867 | G35: 0.1605 | H35: =(150000+199000)/2 -> 174500
A36: Property Value distribution Ꝕ200K-Ꝕ249K | B36: 0.1078 | C36: 0.112 | D36: 0.1053 | E36: 0.0876 | F36: 0.1192 | G36: 0.1025 | H36: =(200000+249000)/2 -> 224500
A37: Property Value distribution Ꝕ250K-Ꝕ299K | B37: 0.0818 | C37: 0.0947 | D37: 0.0761 | E37: 0.0337 | F37: 0.0679 | G37: 0.0582 | H37: =(250000+299000)/2 -> 274500
A38: Property Value distribution Ꝕ300K-Ꝕ399K | B38: 0.2292 | C38: 0.2444 | D38: 0.1894 | E38: 0.1013 | F38: 0.126 | G38: 0.1702 | H38: =(300000+399000)/2 -> 349500
A39: Property Value distribution Ꝕ400K-Ꝕ499K | B39: 0.1151 | C39: 0.1126 | D39: 0.1008 | E39: 0.0291 | F39: 0.0419 | G39: 0.0801 | H39: =(400000+499000)/2 -> 449500
A40: Property Value distribution Ꝕ500K-Ꝕ749K | B40: 0.0528 | C40: 0.0486 | D40: 0.0434 | E40: 0.0183 | F40: 0.0139 | G40: 0.0305 | H40: =(500000+749000)/2 -> 624500
...

Sheet Inflation-Interest
A1: Year | B1: Inflation | C1: Government Overnight Bank Lending Rate | D1: 1-yr risk free rate | E1: 10-yr risk free rate
A2: 1962 | B2: 0.0213 | C2: 0.0307 | D2: 0.0351 | E2: 0.0446
A3: 1963 | B3: 0.0201 | C3: 0.0358 | D3: 0.038 | E3: 0.0452
A4: 1964 | B4: 0.0205 | C4: 0.0394 | D4: 0.0435 | E4: 0.0473
A5: 1965 | B5: 0.0254 | C5: 0.0458 | D5: 0.0468 | E5: 0.0484
A6: 1966 | B6: 0.033 | C6: 0.057 | D6: 0.0587 | E6: 0.0556
A7: 1967 | B7: 0.0274 | C7: 0.0474 | D7: 0.055 | E7: 0.0572
A8: 1968 | B8: 0.0348 | C8: 0.0635 | D8: 0.0641 | E8: 0.0636
A9: 1969 | B9: 0.0406 | C9: 0.091 | D9: 0.0802 | E9: 0.0751
A10: 1970 | B10: 0.0504 | C10: 0.0803 | D10: 0.0777 | E10: 0.0828
A11: 1971 | B11: 0.0472 | C11: 0.0527 | D11: 0.0552 | E11: 0.0694
A12: 1972 | B12: 0.0441 | C12: 0.05 | D12: 0.0559 | E12: 0.0699
A13: 1973 | B13: 0.0676 | C13: 0.0979 | D13: 0.0824 | E13: 0.0771
... A26: 1986 | B26: 0.02 | C26: 0.077 | D26: 0.0727 | E26: 0.0863
A27: 1987 | B27: 0.0313 | D27: 0.0762 | E27: 0.0944
A28: 1988 | B28: 0.0368 | C28: 0.0852 | D28: 0.0861 | E28: 0.0995
A29: 1989 | B29: 0.0483 | C29: 0.1038 | D29: 0.096 | E29: 0.0955
A30: 1990 | B30: 0.051 | C30: 0.0913 | D30: 0.0887 | E30: 0.0962
A31: 1991 | B31: 0.0453 | C31: 0.0646 | D31: 0.066 | E31: 0.0885
A32: 1992 | B32: 0.0426 | C32: 0.0404 | D32: 0.044 | E32: 0.0789
A33: 1993 | B33: 0.0374 | C33: 0.0346 | D33: 0.0389 | E33: 0.0661
A34: 1994 | B34: 0.0319 | C34: 0.0477 | D34: 0.06 | E34: 0.0798
A35: 1995 | B35: 0.0304 | C35: 0.066 | D35: 0.067 | E35: 0.074
A36: 1996 | B36: 0.0283 | C36: 0.0601 | D36: 0.0622 | E36: 0.0726
A37: 1997 | B37: 0.0247 | C37: 0.0619 | D37: 0.0635 | E37: 0.0716
A38: 1998 | B38: 0.0166 | C38: 0.0605 | D38: 0.057 | E38: 0.0593
A39: 1999 | B39: 0.0189 | C39: 0.0563 | D39: 0.0573 | E39: 0.0636
... A42: 2002 | B42: 0.0178 | C42: 0.0192 | D42: 0.0228 | E42: 0.0521
A43: 2003 | B43: =AVERAGE(B44,B42) -> 0.02085 | C43: 0.0131 | D43: 0.0143 | E43: 0.0454
A44: 2004 | B44: 0.0239 | C44: 0.0156 | D44: 0.0215 | E44: 0.0482
A45: 2005 | B45: 0.0281 | C45: 0.0364 | D45: 0.041 | E45: 0.0484
A46: 2006 | B46: 0.0278 | C46: 0.056 | D46: 0.0557 | E46: 0.0541
A47: 2007 | B47: 0.0266 | C47: 0.0567 | D47: 0.0511 | E47: 0.0523
A48: 2008 | B48: 0.037 | C48: 0.0221 | D48: 0.0209 | E48: 0.0414
A49: 2009 | B49: 0.0008 | C49: 0.0022 | D49: 0.0057 | E49: 0.037
A50: 2010 | B50: 0.0151 | C50: 0.0024 | D50: 0.004 | E50: 0.0364
A51: 2011 | B51: 0.03 | C51: 0.0015 | D51: 0.0024 | E51: 0.0316
A52: 2012 | B52: 0.0222 | C52: 0.002 | D52: 0.0024 | E52: 0.0206
A53: 2013 | B53: 0.014 | C53: 0.0016 | D53: 0.0019 | E53: 0.0267
A54: 2014 | B54: 0.0111 | C54: 0.0014 | D54: 0.0018 | E54: 0.0288
...

Sheet SSP Scenarios
B2: Four of the IPCC's SSP Scenarios for Future Atmospheric CO2 Concentrations, Worldwide Population, and GDP
B3: The scenarios produced by the Intergovernmental Panel on Climate Change (IPCC) are referred to as Shared Socioeconomic Pathways (SSPs). The SSPs reflect assumptions about population growth, economic growth, the use of sustainable energy sources versus fossil fuels, as well as other factors which, collectively, lead to a prediction for the trajectory of Green House Gas (GHG) emissions and the resulting atmospheric Carbon Dioxide (CO2) concentrations.
B6: https://ourworldindata.org/explorers/ipcc-scenarios
B8: Scenarios
B9: SSP1‒2.6 | D9: Low Emissions
B10: SSP2‒3.4 | D10: Medium Emissions
B11: SSP3‒6.0 | D11: High Emissions
B12: SSP5‒Baseline | D12: Very High Emissions
D14: Atmospheric CO2 in Parts per Million | I14: World Population (Billions) | N14: Worldwide GDP (Trillions $US) | S14: GDP Per Capita ($US)
D15: SSP1‒ 2.6 | E15: SSP2‒ 3.4 | F15: SSP3‒ 6.0 | G15: SSP5‒ Baseline | I15: SSP1‒ 2.6 | J15: SSP2‒ 3.4 | K15: SSP3‒ 6.0 | L15: SSP5‒ Baseline | N15: SSP1‒ 2.6 | O15: SSP2‒ 3.4 | P15: SSP3‒ 6.0 | Q15: SSP5‒ Baseline | S15: SSP1‒ 2.6 | T15: SSP2‒ 3.4 | U15: SSP3‒ 6.0 | V15: SSP5‒ Baseline
B17: 2005 | D17: 379.85 | E17: 379.85 | F17: 379.85 | G17: 379.85 | I17: 6.53 | J17: 6.5 | K17: 6.49 | L17: 6.51 | N17: 57.41 | O17: 56.53 | P17: 54.73 | Q17: 56.69 | S17: 8791 | T17: 8697 | U17: 8433 | V17: 8708
B18: 2010 | D18: 390.51 | E18: 390.51 | F18: 390.51 | G18: 390.51 | I18: 6.92 | J18: 6.87 | K18: 6.88 | L18: 6.89 | N18: 68.46 | O18: 67.52 | P18: 64.81 | Q18: 67.57 | S18: 9893 | T18: 9828 | U18: 9420 | V18: 9806
B19: 2020 | D19: 414.55 | E19: 414.44 | F19: 417.07 | G19: 417.25 | I19: 7.58 | J19: 7.61 | K19: 7.7 | L19: 7.55 | N19: 101.82 | O19: 101.16 | P19: 97.4 | Q19: 101.9 | S19: 13432 | T19: 13293 | U19: 12649 | V19: 13496
B20: 2030 | D20: 436.54 | E20: 439.28 | F20: 448.55 | G20: 452.77 | I20: 8.06 | J20: 8.26 | K20: 8.51 | L20: 8.05 | N20: 155.85 | O20: 142.89 | P20: 130.23 | Q20: 165.8 | S20: 19336 | T20: 17299 | U20: 15303 | V20: 20596
B21: 2040 | D21: 452.29 | E21: 463.05 | F21: 480.63 | G21: 499.68 | I21: 8.39 | J21: 8.79 | K21: 9.26 | L21: 8.4 | N21: 223.2 | O21: 185.39 | P21: 153.37 | Q21: 260.2 | S21: 26603 | T21: 21091 | U21: 16562 | V21: 30976
B22: 2050 | D22: 460.69 | E22: 483.24 | F22: 511.43 | G22: 559.69 | I22: 8.53 | J22: 9.17 | K22: 9.96 | L22: 8.58 | N22: 291.3 | O22: 230.19 | P22: 171.5 | Q22: 364.7 | S22: 34150 | T22: 25102 | U22: 17218 | V22: 42505
B23: 2060 | D23: 462.9 | E23: 497.49 | F23: 542.95 | G23: 635.79 | I23: 8.49 | J23: 9.38 | K23: 10.57 | L23: 8.59 | N23: 356.29 | O23: 278.62 | P23: 187.41 | Q23: 478.3 | S23: 41965 | T23: 29703 | U23: 17730 | V23: 55681
B24: 2070 | D24: 460.64 | E24: 504.28 | F24: 573.5 | G24: 730.03 | I24: 8.3 | J24: 9.46 | K24: 11.12 | L24: 8.46 | N24: 419.29 | O24: 334.19 | P24: 204.08 | Q24: 605.8 | S24: 50516 | T24: 35326 | U24: 18352 | V24: 71607
B25: 2080 | D25: 453.86 | E25: 504.78 | F25: 599.94 | G25: 841.52 | I25: 7.97 | J25: 9.41 | K25: 11.63 | L25: 8.2 | N25: 475.42 | O25: 394.48 | P25: 221.35 | Q25: 740.6 | S25: 59651 | T25: 41921 | U25: 19032 | V25: 90317
B26: 2090 | D26: 443.09 | E26: 500.71 | F26: 623.13 | G26: 963.84 | I26: 7.51 | J26: 9.25 | K26: 12.13 | L26: 7.83 | N26: 524.88 | O26: 459.9 | P26: 240.09 | Q26: 882.3 | S26: 69890 | T26: 49718 | U26: 19793 | V26: 112681
B27: 2100 | D27: 432.17 | E27: 494.15 | F27: 645.06 | G27: 1088.97 | I27: 6.96 | J27: 9.03 | K27: 12.62 | L27: 7.38 | N27: 565.39 | O27: 531.93 | P27: 261.54 | Q27: 1031 | S27: 81234 | T27: 58906 | U27: 20724 | V27: 139701
B28: 2110 | D28: 421.25 | E28: 487.59 | F28: 666.99 | G28: 1214.1
B29: 2120 | D29: 410.33 | E29: 481.03 | F29: 688.92 | G29: 1339.23
B30: 2130 | D30: 400 | E30: 474.47 | F30: 710.85 | G30: 1464.36
B31: 2140 | D31: 400 | E31: 467.91 | F31: 732.78 | G31: 1589.49
B32: 2150 | D32: 400 | E32: 461.35 | F32: 754.71 | G32: 1714.62
B34: Note: The IPCC's SSP dataset shows projections through 2100. The amounts for 2110 through 2150 were developed by the Society of Actuaries Research Institute solely for the 2023 Student Research Case Study Challenge.
B36: For your information, the explanations below have been copied from the website https://ourworldindata.org/explorers/ipcc-scenarios
B37: What are the Shared Socioeconomic Pathways (SSPs)?
B38: The Shared Socioeconomic Pathways are a set of scenarios which are central to the work of the UN climate reports produced by the Intergovernmental Panel on Climate Change (IPCC).
B40: Why are these scenarios so important for the IPCC report?
B41: • How much greenhouse gas emissions the world emits in the coming decades is unknown. It is up to us. It will depend on what people around the world will do now and in the future.
B42: • In this situation, it’s helpful to create scenarios that cover a range of possible futures. This is what the ‘Shared Socioeconomic Pathways’ (SSPs) are. SSPs are the possible futures that climate
B43: researchers in the IPCC consider in their models.
B44: • SSPs do not tell us what the world will look like. Instead, they tell us what the world could look like.
B45: • The key aspect of these scenarios is the emissions of greenhouse gases that result. This is the key aspect because that what will determine the future of the climate.
B46: • To understand how our emissions might evolve we need to know how the world might change from a socioeconomic and technological perspective. These scenarios therefore differ in their
B47: assumptions about socioeconomic and technological development in the coming decades.
... B113: Full citation: Keywan Riahi, Detlef P. van Vuuren, Elmar Kriegler, Jae Edmonds, Brian C. O’Neill, Shinichiro Fujimori, Nico Bauer, Katherine Calvin, Rob Dellink, Oliver Fricko, Wolfgang Lutz, Alexander Popp, Jesus Crespo Cuaresma, Samir KC, Marian Leimbach, Leiwen Jiang, Tom Kram, Shilpa Rao, Johannes Emmerling, Kristie Ebi, Tomoko Hasegawa, Petr Havlík, Florian Humpenöder, Lara Aleluia Da Silva, Steve Smith, Elke Stehfest, Valentina Bosetti, Jiyong Eom, David Gernaat, Toshihiko Masui, Joeri Rogelj, Jessica Strefler, Laurent Drouet, Volker Krey, Gunnar Luderer, Mathijs Harmsen, Kiyoshi Takahashi, Lavinia Baumstark, Jonathan C. Doelman, Mikiko Kainuma, Zbigniew Klimont, Giacomo Marangoni, Hermann Lotze-Campen, Michael Obersteiner, Andrzej Tabeau, Massimo Tavoni. The Shared Socioeconomic Pathways and Their Energy, Land Use, and Greenhouse Gas Emissions Implications: An overview, Global Environmental Change, Volume 42, Pages 153-168 (2017). (https://www.sciencedirect.com/science/article/pii/S0959378016300681)

Sheet Model
E2: Copyright © 2023 by the Society of Actuaries Research Institute. All rights reserved.
B6: Frequency Projection Model of Minor, Medium, and Major Hazard Events Per Year, as a Function of SSP Scenario | AA6: Illustrative Example
B7: One can view the values below either as the expected number of events per year, or as 1 divided by the "return period". An expectation of 0.25 implies a return period of 4 years (on average, an event occurs every 4 years). | AA7: The purpose of this example is a simplified demonstration
B8: An expected value that exceeds 1.00 indicates a return period of less than one year. For example, an expectation of 3 events per year equates to a return period of 4 months. | AA8: of how the projected number of future hazard events might
AA9: be developed from historical hazard event data. This example
B10: INPUT | AA10: is NOT PRESCRIPTIVE and is purposely very simple. Each team
B11: Enter the Expected Number | AA11: may consider or use other approaches, methods, and/or
B12: Hazard Events in 2020 | AA12: assumptions.
B13: Minor | D13: 42 | T13: The risk amplification factor (RAF) ties the change in risk
B14: Medium | D14: 2.2 | T14: to the change in atmospheric CO2. The RAF is equal to | AA14: Using the Historical Hazard Data, a user can define
B15: Major | D15: 1.2 | T15: the square of A / B, where "A" is the projected future level | AA15: breakpoints for Minor/Medium/Major hazard events.
T16: of CO2 and "B" is the level of CO2 in 2020.
AA17: The following illustrative example projects an expected
D18: SSP1‒ 2.6 | H18: SSP2‒3.4 | L18: SSP3‒6.0 | P18: SSP5‒Baseline | AA18: number of hazard events in 2020 for Region 1 using:
D19: Low Emissions | H19: Medium Emissions | L19: High Emissions | P19: Very High Emissions | T19: Risk Amplification Factor (RAF) | AA19: • Per-event property damage cost breakpoints of
B20: Year | D20: Minor | E20: Medium | F20: Major | H20: Minor | I20: Medium | J20: Major | L20: Minor | M20: Medium | N20: Major | P20: Minor | Q20: Medium | R20: Major | T20: =D18 -> SSP1‒ 2.6 | U20: =H18 -> SSP2‒3.4 | V20: =L18 -> SSP3‒6.0 | W20: =P18 -> SSP5‒Baseline | AA20: 500,000 and 5,000,000
B21: 2020 | D21: =ROUND($D$13,3) -> 42 | E21: =ROUND($D$14,3) -> 2.2 | F21: =ROUND($D$15,3) -> 1.2 | H21: =ROUND($D$13,3) -> 42 | I21: =ROUND($D$14,3) -> 2.2 | J21: =ROUND($D$15,3) -> 1.2 | L21: =ROUND($D$13,3) -> 42 | M21: =ROUND($D$14,3) -> 2.2 | N21: =ROUND($D$15,3) -> 1.2 | P21: =ROUND($D$13,3) -> 42 | Q21: =ROUND($D$14,3) -> 2.2 | R21: =ROUND($D$15,3) -> 1.2 | T21: =ROUND(('SSP Scenarios'!D19/'SSP Scenarios'!D$19)^2,5) -> 1 | U21: =ROUND(('SSP Scenarios'!E19/'SSP Scenarios'!E$19)^2,5) -> 1 | V21: =ROUND(('SSP Scenarios'!F19/'SSP Scenarios'!F$19)^2,5) -> 1 | W21: =ROUND(('SSP Scenarios'!G19/'SSP Scenarios'!G$19)^2,5) -> 1 | AA21: • Simple average between 1990 and 2020
B22: 2021 | D22: =ROUND(D$21*$T22,3) -> 42.457 | E22: =ROUND(E$21*$T22,3) -> 2.224 | F22: =ROUND(F$21*$T22,3) -> 1.213 | H22: =ROUND(H$21*$U22,3) -> 42.519 | I22: =ROUND(I$21*$U22,3) -> 2.227 | J22: =ROUND(J$21*$U22,3) -> 1.215 | L22: =ROUND(L$21*$V22,3) -> 42.658 | M22: =ROUND(M$21*$V22,3) -> 2.234 | N22: =ROUND(N$21*$V22,3) -> 1.219 | P22: =ROUND(P$21*$W22,3) -> 42.746 | Q22: =ROUND(Q$21*$W22,3) -> 2.239 | R22: =ROUND(R$21*$W22,3) -> 1.221 | T22: =T21+(T$31-T$21)/($B$31-$B$21) -> 1.01089 | U22: =U21+(U$31-U$21)/($B$31-$B$21) -> 1.012346 | V22: =V21+(V$31-V$21)/($B$31-$B$21) -> 1.015665 | W22: =W21+(W$31-W$21)/($B$31-$B$21) -> 1.01775 | AA22: • Ignores duration, fatalities, injuries and type of hazard event
B23: 2022 | D23: =ROUND(D$21*$T23,3) -> 42.915 | E23: =ROUND(E$21*$T23,3) -> 2.248 | F23: =ROUND(F$21*$T23,3) -> 1.226 | H23: =ROUND(H$21*$U23,3) -> 43.037 | I23: =ROUND(I$21*$U23,3) -> 2.254 | J23: =ROUND(J$21*$U23,3) -> 1.23 | L23: =ROUND(L$21*$V23,3) -> 43.316 | M23: =ROUND(M$21*$V23,3) -> 2.269 | N23: =ROUND(N$21*$V23,3) -> 1.238 | P23: =ROUND(P$21*$W23,3) -> 43.491 | Q23: =ROUND(Q$21*$W23,3) -> 2.278 | R23: =ROUND(R$21*$W23,3) -> 1.243 | T23: =T22+(T$31-T$21)/($B$31-$B$21) -> 1.02178 | U23: =U22+(U$31-U$21)/($B$31-$B$21) -> 1.024692 | V23: =V22+(V$31-V$21)/($B$31-$B$21) -> 1.03133 | W23: =W22+(W$31-W$21)/($B$31-$B$21) -> 1.0355
B24: 2023 | D24: =ROUND(D$21*$T24,3) -> 43.372 | E24: =ROUND(E$21*$T24,3) -> 2.272 | F24: =ROUND(F$21*$T24,3) -> 1.239 | H24: =ROUND(H$21*$U24,3) -> 43.556 | I24: =ROUND(I$21*$U24,3) -> 2.281 | J24: =ROUND(J$21*$U24,3) -> 1.244 | L24: =ROUND(L$21*$V24,3) -> 43.974 | M24: =ROUND(M$21*$V24,3) -> 2.303 | N24: =ROUND(N$21*$V24,3) -> 1.256 | P24: =ROUND(P$21*$W24,3) -> 44.237 | Q24: =ROUND(Q$21*$W24,3) -> 2.317 | R24: =ROUND(R$21*$W24,3) -> 1.264 | T24: =T23+(T$31-T$21)/($B$31-$B$21) -> 1.03267 | U24: =U23+(U$31-U$21)/($B$31-$B$21) -> 1.037038 | V24: =V23+(V$31-V$21)/($B$31-$B$21) -> 1.046995 | W24: =W23+(W$31-W$21)/($B$31-$B$21) -> 1.05325 | AA24: The result is a simple approximation that may be entered as
B25: 2024 | D25: =ROUND(D$21*$T25,3) -> 43.83 | E25: =ROUND(E$21*$T25,3) -> 2.296 | F25: =ROUND(F$21*$T25,3) -> 1.252 | H25: =ROUND(H$21*$U25,3) -> 44.074 | I25: =ROUND(I$21*$U25,3) -> 2.309 | J25: =ROUND(J$21*$U25,3) -> 1.259 | L25: =ROUND(L$21*$V25,3) -> 44.632 | M25: =ROUND(M$21*$V25,3) -> 2.338 | N25: =ROUND(N$21*$V25,3) -> 1.275 | P25: =ROUND(P$21*$W25,3) -> 44.982 | Q25: =ROUND(Q$21*$W25,3) -> 2.356 | R25: =ROUND(R$21*$W25,3) -> 1.285 | T25: =T24+(T$31-T$21)/($B$31-$B$21) -> 1.04356 | U25: =U24+(U$31-U$21)/($B$31-$B$21) -> 1.049384 | V25: =V24+(V$31-V$21)/($B$31-$B$21) -> 1.06266 | W25: =W24+(W$31-W$21)/($B$31-$B$21) -> 1.071 | AA25: starting inputs in model to the left.
B26: 2025 | D26: =ROUND(D$21*$T26,3) -> 44.287 | E26: =ROUND(E$21*$T26,3) -> 2.32 | F26: =ROUND(F$21*$T26,3) -> 1.265 | H26: =ROUND(H$21*$U26,3) -> 44.593 | I26: =ROUND(I$21*$U26,3) -> 2.336 | J26: =ROUND(J$21*$U26,3) -> 1.274 | L26: =ROUND(L$21*$V26,3) -> 45.29 | M26: =ROUND(M$21*$V26,3) -> 2.372 | N26: =ROUND(N$21*$V26,3) -> 1.294 | P26: =ROUND(P$21*$W26,3) -> 45.728 | Q26: =ROUND(Q$21*$W26,3) -> 2.395 | R26: =ROUND(R$21*$W26,3) -> 1.307 | T26: =T25+(T$31-T$21)/($B$31-$B$21) -> 1.05445 | U26: =U25+(U$31-U$21)/($B$31-$B$21) -> 1.06173 | V26: =V25+(V$31-V$21)/($B$31-$B$21) -> 1.078325 | W26: =W25+(W$31-W$21)/($B$31-$B$21) -> 1.08875
B27: 2026 | D27: =ROUND(D$21*$T27,3) -> 44.744 | E27: =ROUND(E$21*$T27,3) -> 2.344 | F27: =ROUND(F$21*$T27,3) -> 1.278 | H27: =ROUND(H$21*$U27,3) -> 45.111 | I27: =ROUND(I$21*$U27,3) -> 2.363 | J27: =ROUND(J$21*$U27,3) -> 1.289 | L27: =ROUND(L$21*$V27,3) -> 45.948 | M27: =ROUND(M$21*$V27,3) -> 2.407 | N27: =ROUND(N$21*$V27,3) -> 1.313 | P27: =ROUND(P$21*$W27,3) -> 46.473 | Q27: =ROUND(Q$21*$W27,3) -> 2.434 | R27: =ROUND(R$21*$W27,3) -> 1.328 | T27: =T26+(T$31-T$21)/($B$31-$B$21) -> 1.06534 | U27: =U26+(U$31-U$21)/($B$31-$B$21) -> 1.074076 | V27: =V26+(V$31-V$21)/($B$31-$B$21) -> 1.09399 | W27: =W26+(W$31-W$21)/($B$31-$B$21) -> 1.1065 | AB27: Minor | AC27: Medium | AD27: Major
B28: 2027 | D28: =ROUND(D$21*$T28,3) -> 45.202 | E28: =ROUND(E$21*$T28,3) -> 2.368 | F28: =ROUND(F$21*$T28,3) -> 1.291 | H28: =ROUND(H$21*$U28,3) -> 45.63 | I28: =ROUND(I$21*$U28,3) -> 2.39 | J28: =ROUND(J$21*$U28,3) -> 1.304 | L28: =ROUND(L$21*$V28,3) -> 46.606 | M28: =ROUND(M$21*$V28,3) -> 2.441 | N28: =ROUND(N$21*$V28,3) -> 1.332 | P28: =ROUND(P$21*$W28,3) -> 47.219 | Q28: =ROUND(Q$21*$W28,3) -> 2.473 | R28: =ROUND(R$21*$W28,3) -> 1.349 | T28: =T27+(T$31-T$21)/($B$31-$B$21) -> 1.07623 | U28: =U27+(U$31-U$21)/($B$31-$B$21) -> 1.086422 | V28: =V27+(V$31-V$21)/($B$31-$B$21) -> 1.109655 | W28: =W27+(W$31-W$21)/($B$31-$B$21) -> 1.12425 | AA28: Average | AB28: =AVERAGE(AB33:AB63) -> 5.9677419 | AC28: =AVERAGE(AC33:AC63) -> 1.6451613 | AD28: =AVERAGE(AD33:AD63) -> 0.61290323
B29: 2028 | D29: =ROUND(D$21*$T29,3) -> 45.659 | E29: =ROUND(E$21*$T29,3) -> 2.392 | F29: =ROUND(F$21*$T29,3) -> 1.305 | H29: =ROUND(H$21*$U29,3) -> 46.148 | I29: =ROUND(I$21*$U29,3) -> 2.417 | J29: =ROUND(J$21*$U29,3) -> 1.319 | L29: =ROUND(L$21*$V29,3) -> 47.263 | M29: =ROUND(M$21*$V29,3) -> 2.476 | N29: =ROUND(N$21*$V29,3) -> 1.35 | P29: =ROUND(P$21*$W29,3) -> 47.964 | Q29: =ROUND(Q$21*$W29,3) -> 2.512 | R29: =ROUND(R$21*$W29,3) -> 1.37 | T29: =T28+(T$31-T$21)/($B$31-$B$21) -> 1.08712 | U29: =U28+(U$31-U$21)/($B$31-$B$21) -> 1.098768 | V29: =V28+(V$31-V$21)/($B$31-$B$21) -> 1.12532 | W29: =W28+(W$31-W$21)/($B$31-$B$21) -> 1.142 | AA29: Rounded | AB29: =ROUND(AB28,1) -> 6 | AC29: =ROUND(AC28,1) -> 1.6 | AD29: =ROUND(AD28,1) -> 0.6
B30: 2029 | D30: =ROUND(D$21*$T30,3) -> 46.116 | E30: =ROUND(E$21*$T30,3) -> 2.416 | F30: =ROUND(F$21*$T30,3) -> 1.318 | H30: =ROUND(H$21*$U30,3) -> 46.667 | I30: =ROUND(I$21*$U30,3) -> 2.444 | J30: =ROUND(J$21*$U30,3) -> 1.333 | L30: =ROUND(L$21*$V30,3) -> 47.921 | M30: =ROUND(M$21*$V30,3) -> 2.51 | N30: =ROUND(N$21*$V30,3) -> 1.369 | P30: =ROUND(P$21*$W30,3) -> 48.71 | Q30: =ROUND(Q$21*$W30,3) -> 2.551 | R30: =ROUND(R$21*$W30,3) -> 1.392 | T30: =T29+(T$31-T$21)/($B$31-$B$21) -> 1.09801 | U30: =U29+(U$31-U$21)/($B$31-$B$21) -> 1.111114 | V30: =V29+(V$31-V$21)/($B$31-$B$21) -> 1.140985 | W30: =W29+(W$31-W$21)/($B$31-$B$21) -> 1.15975
B31: 2030 | D31: =ROUND(D$21*$T31,3) -> 46.574 | E31: =ROUND(E$21*$T31,3) -> 2.44 | F31: =ROUND(F$21*$T31,3) -> 1.331 | H31: =ROUND(H$21*$U31,3) -> 47.185 | I31: =ROUND(I$21*$U31,3) -> 2.472 | J31: =ROUND(J$21*$U31,3) -> 1.348 | L31: =ROUND(L$21*$V31,3) -> 48.579 | M31: =ROUND(M$21*$V31,3) -> 2.545 | N31: =ROUND(N$21*$V31,3) -> 1.388 | P31: =ROUND(P$21*$W31,3) -> 49.455 | Q31: =ROUND(Q$21*$W31,3) -> 2.591 | R31: =ROUND(R$21*$W31,3) -> 1.413 | T31: =ROUND(('SSP Scenarios'!D20/'SSP Scenarios'!D$19)^2,5) -> 1.1089 | U31: =ROUND(('SSP Scenarios'!E20/'SSP Scenarios'!E$19)^2,5) -> 1.12346 | V31: =ROUND(('SSP Scenarios'!F20/'SSP Scenarios'!F$19)^2,5) -> 1.15665 | W31: =ROUND(('SSP Scenarios'!G20/'SSP Scenarios'!G$19)^2,5) -> 1.1775 | AA31: Historical Hazard Data
B32: =B31+10 -> 2040 | D32: =ROUND(D$21*$T32,3) -> 49.995 | E32: =ROUND(E$21*$T32,3) -> 2.619 | F32: =ROUND(F$21*$T32,3) -> 1.428 | H32: =ROUND(H$21*$U32,3) -> 52.43 | I32: =ROUND(I$21*$U32,3) -> 2.746 | J32: =ROUND(J$21*$U32,3) -> 1.498 | L32: =ROUND(L$21*$V32,3) -> 55.777 | M32: =ROUND(M$21*$V32,3) -> 2.922 | N32: =ROUND(N$21*$V32,3) -> 1.594 | P32: =ROUND(P$21*$W32,3) -> 60.234 | Q32: =ROUND(Q$21*$W32,3) -> 3.155 | R32: =ROUND(R$21*$W32,3) -> 1.721 | T32: =ROUND(('SSP Scenarios'!D21/'SSP Scenarios'!D$19)^2,5) -> 1.19036 | U32: =ROUND(('SSP Scenarios'!E21/'SSP Scenarios'!E$19)^2,5) -> 1.24834 | V32: =ROUND(('SSP Scenarios'!F21/'SSP Scenarios'!F$19)^2,5) -> 1.32802 | W32: =ROUND(('SSP Scenarios'!G21/'SSP Scenarios'!G$19)^2,5) -> 1.43414 | AB32: Minor | AC32: Medium | AD32: Major
B33: =B32+10 -> 2050 | D33: =ROUND(D$21*$T33,3) -> 51.87 | E33: =ROUND(E$21*$T33,3) -> 2.717 | F33: =ROUND(F$21*$T33,3) -> 1.482 | H33: =ROUND(H$21*$U33,3) -> 57.102 | I33: =ROUND(I$21*$U33,3) -> 2.991 | J33: =ROUND(J$21*$U33,3) -> 1.631 | L33: =ROUND(L$21*$V33,3) -> 63.155 | M33: =ROUND(M$21*$V33,3) -> 3.308 | N33: =ROUND(N$21*$V33,3) -> 1.804 | P33: =ROUND(P$21*$W33,3) -> 75.571 | Q33: =ROUND(Q$21*$W33,3) -> 3.958 | R33: =ROUND(R$21*$W33,3) -> 2.159 | T33: =ROUND(('SSP Scenarios'!D22/'SSP Scenarios'!D$19)^2,5) -> 1.23499 | U33: =ROUND(('SSP Scenarios'!E22/'SSP Scenarios'!E$19)^2,5) -> 1.35957 | V33: =ROUND(('SSP Scenarios'!F22/'SSP Scenarios'!F$19)^2,5) -> 1.50368 | W33: =ROUND(('SSP Scenarios'!G22/'SSP Scenarios'!G$19)^2,5) -> 1.7993 | AA33: 1990 | AB33: 9 | AC33: 4 | AD33: 0
B34: =B33+10 -> 2060 | D34: =ROUND(D$21*$T34,3) -> 52.369 | E34: =ROUND(E$21*$T34,3) -> 2.743 | F34: =ROUND(F$21*$T34,3) -> 1.496 | H34: =ROUND(H$21*$U34,3) -> 60.519 | I34: =ROUND(I$21*$U34,3) -> 3.17 | J34: =ROUND(J$21*$U34,3) -> 1.729 | L34: =ROUND(L$21*$V34,3) -> 71.179 | M34: =ROUND(M$21*$V34,3) -> 3.728 | N34: =ROUND(N$21*$V34,3) -> 2.034 | P34: =ROUND(P$21*$W34,3) -> 97.518 | Q34: =ROUND(Q$21*$W34,3) -> 5.108 | R34: =ROUND(R$21*$W34,3) -> 2.786 | T34: =ROUND(('SSP Scenarios'!D23/'SSP Scenarios'!D$19)^2,5) -> 1.24687 | U34: =ROUND(('SSP Scenarios'!E23/'SSP Scenarios'!E$19)^2,5) -> 1.44094 | V34: =ROUND(('SSP Scenarios'!F23/'SSP Scenarios'!F$19)^2,5) -> 1.69473 | W34: =ROUND(('SSP Scenarios'!G23/'SSP Scenarios'!G$19)^2,5) -> 2.32185 | AA34: 1991 | AB34: 7 | AC34: 3 | AD34: 0
B35: =B34+10 -> 2070 | D35: =ROUND(D$21*$T35,3) -> 51.858 | E35: =ROUND(E$21*$T35,3) -> 2.716 | F35: =ROUND(F$21*$T35,3) -> 1.482 | H35: =ROUND(H$21*$U35,3) -> 62.183 | I35: =ROUND(I$21*$U35,3) -> 3.257 | J35: =ROUND(J$21*$U35,3) -> 1.777 | L35: =ROUND(L$21*$V35,3) -> 79.414 | M35: =ROUND(M$21*$V35,3) -> 4.16 | N35: =ROUND(N$21*$V35,3) -> 2.269 | P35: =ROUND(P$21*$W35,3) -> 128.57 | Q35: =ROUND(Q$21*$W35,3) -> 6.735 | R35: =ROUND(R$21*$W35,3) -> 3.673 | T35: =ROUND(('SSP Scenarios'!D24/'SSP Scenarios'!D$19)^2,5) -> 1.23472 | U35: =ROUND(('SSP Scenarios'!E24/'SSP Scenarios'!E$19)^2,5) -> 1.48054 | V35: =ROUND(('SSP Scenarios'!F24/'SSP Scenarios'!F$19)^2,5) -> 1.89081 | W35: =ROUND(('SSP Scenarios'!G24/'SSP Scenarios'!G$19)^2,5) -> 3.06118 | AA35: 1992 | AB35: 7 | AC35: 3 | AD35: 0
B36: =B35+10 -> 2080 | D36: =ROUND(D$21*$T36,3) -> 50.343 | E36: =ROUND(E$21*$T36,3) -> 2.637 | F36: =ROUND(F$21*$T36,3) -> 1.438 | H36: =ROUND(H$21*$U36,3) -> 62.306 | I36: =ROUND(I$21*$U36,3) -> 3.264 | J36: =ROUND(J$21*$U36,3) -> 1.78 | L36: =ROUND(L$21*$V36,3) -> 86.906 | M36: =ROUND(M$21*$V36,3) -> 4.552 | N36: =ROUND(N$21*$V36,3) -> 2.483 | P36: =ROUND(P$21*$W36,3) -> 170.838 | Q36: =ROUND(Q$21*$W36,3) -> 8.949 | R36: =ROUND(R$21*$W36,3) -> 4.881 | T36: =ROUND(('SSP Scenarios'!D25/'SSP Scenarios'!D$19)^2,5) -> 1.19864 | U36: =ROUND(('SSP Scenarios'!E25/'SSP Scenarios'!E$19)^2,5) -> 1.48348 | V36: =ROUND(('SSP Scenarios'!F25/'SSP Scenarios'!F$19)^2,5) -> 2.06918 | W36: =ROUND(('SSP Scenarios'!G25/'SSP Scenarios'!G$19)^2,5) -> 4.06758 | AA36: 1993 | AB36: 13 | AC36: 4 | AD36: 2
B37: =B36+10 -> 2090 | D37: =ROUND(D$21*$T37,3) -> 47.982 | E37: =ROUND(E$21*$T37,3) -> 2.513 | F37: =ROUND(F$21*$T37,3) -> 1.371 | H37: =ROUND(H$21*$U37,3) -> 61.305 | I37: =ROUND(I$21*$U37,3) -> 3.211 | J37: =ROUND(J$21*$U37,3) -> 1.752 | L37: =ROUND(L$21*$V37,3) -> 93.754 | M37: =ROUND(M$21*$V37,3) -> 4.911 | N37: =ROUND(N$21*$V37,3) -> 2.679 | P37: =ROUND(P$21*$W37,3) -> 224.113 | Q37: =ROUND(Q$21*$W37,3) -> 11.739 | R37: =ROUND(R$21*$W37,3) -> 6.403 | T37: =ROUND(('SSP Scenarios'!D26/'SSP Scenarios'!D$19)^2,5) -> 1.14243 | U37: =ROUND(('SSP Scenarios'!E26/'SSP Scenarios'!E$19)^2,5) -> 1.45965 | V37: =ROUND(('SSP Scenarios'!F26/'SSP Scenarios'!F$19)^2,5) -> 2.23223 | W37: =ROUND(('SSP Scenarios'!G26/'SSP Scenarios'!G$19)^2,5) -> 5.33602 | AA37: 1994 | AB37: 16 | AC37: 3 | AD37: 0
B38: =B37+10 -> 2100 | D38: =ROUND(D$21*$T38,3) -> 45.646 | E38: =ROUND(E$21*$T38,3) -> 2.391 | F38: =ROUND(F$21*$T38,3) -> 1.304 | H38: =ROUND(H$21*$U38,3) -> 59.71 | I38: =ROUND(I$21*$U38,3) -> 3.128 | J38: =ROUND(J$21*$U38,3) -> 1.706 | L38: =ROUND(L$21*$V38,3) -> 100.469 | M38: =ROUND(M$21*$V38,3) -> 5.263 | N38: =ROUND(N$21*$V38,3) -> 2.871 | P38: =ROUND(P$21*$W38,3) -> 286.08 | Q38: =ROUND(Q$21*$W38,3) -> 14.985 | R38: =ROUND(R$21*$W38,3) -> 8.174 | T38: =ROUND(('SSP Scenarios'!D27/'SSP Scenarios'!D$19)^2,5) -> 1.08681 | U38: =ROUND(('SSP Scenarios'!E27/'SSP Scenarios'!E$19)^2,5) -> 1.42166 | V38: =ROUND(('SSP Scenarios'!F27/'SSP Scenarios'!F$19)^2,5) -> 2.39212 | W38: =ROUND(('SSP Scenarios'!G27/'SSP Scenarios'!G$19)^2,5) -> 6.81144 | AA38: 1995 | AB38: 14 | AC38: 4 | AD38: 3
B39: =B38+10 -> 2110 | D39: =ROUND(D$21*$T39,3) -> 43.369 | E39: =ROUND(E$21*$T39,3) -> 2.272 | F39: =ROUND(F$21*$T39,3) -> 1.239 | H39: =ROUND(H$21*$U39,3) -> 58.135 | I39: =ROUND(I$21*$U39,3) -> 3.045 | J39: =ROUND(J$21*$U39,3) -> 1.661 | L39: =ROUND(L$21*$V39,3) -> 107.416 | M39: =ROUND(M$21*$V39,3) -> 5.627 | N39: =ROUND(N$21*$V39,3) -> 3.069 | P39: =ROUND(P$21*$W39,3) -> 355.603 | Q39: =ROUND(Q$21*$W39,3) -> 18.627 | R39: =ROUND(R$21*$W39,3) -> 10.16 | T39: =ROUND(('SSP Scenarios'!D28/'SSP Scenarios'!D$19)^2,5) -> 1.03259 | U39: =ROUND(('SSP Scenarios'!E28/'SSP Scenarios'!E$19)^2,5) -> 1.38416 | V39: =ROUND(('SSP Scenarios'!F28/'SSP Scenarios'!F$19)^2,5) -> 2.55753 | W39: =ROUND(('SSP Scenarios'!G28/'SSP Scenarios'!G$19)^2,5) -> 8.46674 | AA39: 1996 | AB39: 16 | AC39: 2 | AD39: 1
B40: =B39+10 -> 2120 | D40: =ROUND(D$21*$T40,3) -> 41.149 | E40: =ROUND(E$21*$T40,3) -> 2.155 | F40: =ROUND(F$21*$T40,3) -> 1.176 | H40: =ROUND(H$21*$U40,3) -> 56.581 | I40: =ROUND(I$21*$U40,3) -> 2.964 | J40: =ROUND(J$21*$U40,3) -> 1.617 | L40: =ROUND(L$21*$V40,3) -> 114.596 | M40: =ROUND(M$21*$V40,3) -> 6.003 | N40: =ROUND(N$21*$V40,3) -> 3.274 | P40: =ROUND(P$21*$W40,3) -> 432.68 | Q40: =ROUND(Q$21*$W40,3) -> 22.664 | R40: =ROUND(R$21*$W40,3) -> 12.362 | T40: =ROUND(('SSP Scenarios'!D29/'SSP Scenarios'!D$19)^2,5) -> 0.97974 | U40: =ROUND(('SSP Scenarios'!E29/'SSP Scenarios'!E$19)^2,5) -> 1.34717 | V40: =ROUND(('SSP Scenarios'!F29/'SSP Scenarios'!F$19)^2,5) -> 2.72847 | W40: =ROUND(('SSP Scenarios'!G29/'SSP Scenarios'!G$19)^2,5) -> 10.30191 | AA40: 1997 | AB40: 3 | AC40: 2 | AD40: 0
B41: =B40+10 -> 2130 | D41: =ROUND(D$21*$T41,3) -> 39.104 | E41: =ROUND(E$21*$T41,3) -> 2.048 | F41: =ROUND(F$21*$T41,3) -> 1.117 | H41: =ROUND(H$21*$U41,3) -> 55.048 | I41: =ROUND(I$21*$U41,3) -> 2.883 | J41: =ROUND(J$21*$U41,3) -> 1.573 | L41: =ROUND(L$21*$V41,3) -> 122.008 | M41: =ROUND(M$21*$V41,3) -> 6.391 | N41: =ROUND(N$21*$V41,3) -> 3.486 | P41: =ROUND(P$21*$W41,3) -> 517.312 | Q41: =ROUND(Q$21*$W41,3) -> 27.097 | R41: =ROUND(R$21*$W41,3) -> 14.78 | T41: =ROUND(('SSP Scenarios'!D30/'SSP Scenarios'!D$19)^2,5) -> 0.93104 | U41: =ROUND(('SSP Scenarios'!E30/'SSP Scenarios'!E$19)^2,5) -> 1.31067 | V41: =ROUND(('SSP Scenarios'!F30/'SSP Scenarios'!F$19)^2,5) -> 2.90495 | W41: =ROUND(('SSP Scenarios'!G30/'SSP Scenarios'!G$19)^2,5) -> 12.31695 | AA41: 1998 | AB41: 4 | AC41: 1 | AD41: 0
B42: =B41+10 -> 2140 | D42: =ROUND(D$21*$T42,3) -> 39.104 | E42: =ROUND(E$21*$T42,3) -> 2.048 | F42: =ROUND(F$21*$T42,3) -> 1.117 | H42: =ROUND(H$21*$U42,3) -> 53.537 | I42: =ROUND(I$21*$U42,3) -> 2.804 | J42: =ROUND(J$21*$U42,3) -> 1.53 | L42: =ROUND(L$21*$V42,3) -> 129.652 | M42: =ROUND(M$21*$V42,3) -> 6.791 | N42: =ROUND(N$21*$V42,3) -> 3.704 | P42: =ROUND(P$21*$W42,3) -> 609.498 | Q42: =ROUND(Q$21*$W42,3) -> 31.926 | R42: =ROUND(R$21*$W42,3) -> 17.414 | T42: =ROUND(('SSP Scenarios'!D31/'SSP Scenarios'!D$19)^2,5) -> 0.93104 | U42: =ROUND(('SSP Scenarios'!E31/'SSP Scenarios'!E$19)^2,5) -> 1.27468 | V42: =ROUND(('SSP Scenarios'!F31/'SSP Scenarios'!F$19)^2,5) -> 3.08695 | W42: =ROUND(('SSP Scenarios'!G31/'SSP Scenarios'!G$19)^2,5) -> 14.51185 | AA42: 1999 | AB42: 5 | AC42: 1 | AD42: 1
B43: =B42+10 -> 2150 | D43: =ROUND(D$21*$T43,3) -> 39.104 | E43: =ROUND(E$21*$T43,3) -> 2.048 | F43: =ROUND(F$21*$T43,3) -> 1.117 | H43: =ROUND(H$21*$U43,3) -> 52.046 | I43: =ROUND(I$21*$U43,3) -> 2.726 | J43: =ROUND(J$21*$U43,3) -> 1.487 | L43: =ROUND(L$21*$V43,3) -> 137.528 | M43: =ROUND(M$21*$V43,3) -> 7.204 | N43: =ROUND(N$21*$V43,3) -> 3.929 | P43: =ROUND(P$21*$W43,3) -> 709.238 | Q43: =ROUND(Q$21*$W43,3) -> 37.151 | R43: =ROUND(R$21*$W43,3) -> 20.264 | T43: =ROUND(('SSP Scenarios'!D32/'SSP Scenarios'!D$19)^2,5) -> 0.93104 | U43: =ROUND(('SSP Scenarios'!E32/'SSP Scenarios'!E$19)^2,5) -> 1.23919 | V43: =ROUND(('SSP Scenarios'!F32/'SSP Scenarios'!F$19)^2,5) -> 3.27448 | W43: =ROUND(('SSP Scenarios'!G32/'SSP Scenarios'!G$19)^2,5) -> 16.88663 | AA43: 2000 | AB43: 4 | AC43: 1 | AD43: 1
AA44: 2001 | AB44: 0 | AC44: 0 | AD44: 0
...

Sheet Economic Projections
A1: Census Projections using 2020 as base value of 1 | G1: GDP Projections using 2020 as base value of 1 | M1: GDP per capita projections using 2020 as base value of 1
B2: SSP1 | C2: SSP2 | D2: SSP3 | E2: SSP5 | H2: SSP1 | I2: SSP2 | J2: SSP3 | K2: SSP5 | N2: SSP1 | O2: SSP2 | P2: SSP3 | Q2: SSP5
A3: 2020 | B3: 1 | C3: 1 | D3: 1 | E3: 1 | G3: 2020 | H3: 1 | I3: 1 | J3: 1 | K3: 1 | M3: 2020 | N3: 1 | O3: 1 | P3: 1 | Q3: 1
A4: 2021 | B4: =B3+(B$13-B$3)/($A$13-$A$3) -> 1.0063325 | C4: =C3+(C$13-C$3)/($A$13-$A$3) -> 1.0085414 | D4: =D3+(D$13-D$3)/($A$13-$A$3) -> 1.0105195 | E4: =E3+(E$13-E$3)/($A$13-$A$3) -> 1.0066225 | G4: 2021 | H4: =H3+(H$13-H$3)/($A$13-$A$3) -> 1.0530642 | I4: =I3+(I$13-I$3)/($A$13-$A$3) -> 1.0412515 | J4: =J3+(J$13-J$3)/($A$13-$A$3) -> 1.0337064 | K4: =K3+(K$13-K$3)/($A$13-$A$3) -> 1.0627085 | M4: 2021 | N4: =N3+(N$13-N$3)/($A$13-$A$3) -> 1.0439547 | O4: =O3+(O$13-O$3)/($A$13-$A$3) -> 1.0301362 | P4: =P3+(P$13-P$3)/($A$13-$A$3) -> 1.0209819 | Q4: =Q3+(Q$13-Q$3)/($A$13-$A$3) -> 1.0526082
A5: 2022 | B5: =B4+(B$13-B$3)/($A$13-$A$3) -> 1.0126649 | C5: =C4+(C$13-C$3)/($A$13-$A$3) -> 1.0170828 | D5: =D4+(D$13-D$3)/($A$13-$A$3) -> 1.021039 | E5: =E4+(E$13-E$3)/($A$13-$A$3) -> 1.013245 | G5: 2022 | H5: =H4+(H$13-H$3)/($A$13-$A$3) -> 1.1061285 | I5: =I4+(I$13-I$3)/($A$13-$A$3) -> 1.082503 | J5: =J4+(J$13-J$3)/($A$13-$A$3) -> 1.0674127 | K5: =K4+(K$13-K$3)/($A$13-$A$3) -> 1.1254171 | M5: 2022 | N5: =N4+(N$13-N$3)/($A$13-$A$3) -> 1.0879095 | O5: =O4+(O$13-O$3)/($A$13-$A$3) -> 1.0602723 | P5: =P4+(P$13-P$3)/($A$13-$A$3) -> 1.0419638 | Q5: =Q4+(Q$13-Q$3)/($A$13-$A$3) -> 1.1052164
A6: 2023 | B6: =B5+(B$13-B$3)/($A$13-$A$3) -> 1.0189974 | C6: =C5+(C$13-C$3)/($A$13-$A$3) -> 1.0256242 | D6: =D5+(D$13-D$3)/($A$13-$A$3) -> 1.0315584 | E6: =E5+(E$13-E$3)/($A$13-$A$3) -> 1.0198675 | G6: 2023 | H6: =H5+(H$13-H$3)/($A$13-$A$3) -> 1.1591927 | I6: =I5+(I$13-I$3)/($A$13-$A$3) -> 1.1237544 | J6: =J5+(J$13-J$3)/($A$13-$A$3) -> 1.1011191 | K6: =K5+(K$13-K$3)/($A$13-$A$3) -> 1.1881256 | M6: 2023 | N6: =N5+(N$13-N$3)/($A$13-$A$3) -> 1.1318642 | O6: =O5+(O$13-O$3)/($A$13-$A$3) -> 1.0904085 | P6: =P5+(P$13-P$3)/($A$13-$A$3) -> 1.0629457 | Q6: =Q5+(Q$13-Q$3)/($A$13-$A$3) -> 1.1578245
A7: 2024 | B7: =B6+(B$13-B$3)/($A$13-$A$3) -> 1.0253298 | C7: =C6+(C$13-C$3)/($A$13-$A$3) -> 1.0341656 | D7: =D6+(D$13-D$3)/($A$13-$A$3) -> 1.0420779 | E7: =E6+(E$13-E$3)/($A$13-$A$3) -> 1.0264901 | G7: 2024 | H7: =H6+(H$13-H$3)/($A$13-$A$3) -> 1.2122569 | I7: =I6+(I$13-I$3)/($A$13-$A$3) -> 1.1650059 | J7: =J6+(J$13-J$3)/($A$13-$A$3) -> 1.1348255 | K7: =K6+(K$13-K$3)/($A$13-$A$3) -> 1.2508342 | M7: 2024 | N7: =N6+(N$13-N$3)/($A$13-$A$3) -> 1.1758189 | O7: =O6+(O$13-O$3)/($A$13-$A$3) -> 1.1205446 | P7: =P6+(P$13-P$3)/($A$13-$A$3) -> 1.0839276 | Q7: =Q6+(Q$13-Q$3)/($A$13-$A$3) -> 1.2104327
A8: 2025 | B8: =B7+(B$13-B$3)/($A$13-$A$3) -> 1.0316623 | C8: =C7+(C$13-C$3)/($A$13-$A$3) -> 1.042707 | D8: =D7+(D$13-D$3)/($A$13-$A$3) -> 1.0525974 | E8: =E7+(E$13-E$3)/($A$13-$A$3) -> 1.0331126 | G8: 2025 | H8: =H7+(H$13-H$3)/($A$13-$A$3) -> 1.2653212 | I8: =I7+(I$13-I$3)/($A$13-$A$3) -> 1.2062574 | J8: =J7+(J$13-J$3)/($A$13-$A$3) -> 1.1685318 | K8: =K7+(K$13-K$3)/($A$13-$A$3) -> 1.3135427 | M8: 2025 | N8: =N7+(N$13-N$3)/($A$13-$A$3) -> 1.2197737 | O8: =O7+(O$13-O$3)/($A$13-$A$3) -> 1.1506808 | P8: =P7+(P$13-P$3)/($A$13-$A$3) -> 1.1049095 | Q8: =Q7+(Q$13-Q$3)/($A$13-$A$3) -> 1.2630409
A9: 2026 | B9: =B8+(B$13-B$3)/($A$13-$A$3) -> 1.0379947 | C9: =C8+(C$13-C$3)/($A$13-$A$3) -> 1.0512484 | D9: =D8+(D$13-D$3)/($A$13-$A$3) -> 1.0631169 | E9: =E8+(E$13-E$3)/($A$13-$A$3) -> 1.0397351 | G9: 2026 | H9: =H8+(H$13-H$3)/($A$13-$A$3) -> 1.3183854 | I9: =I8+(I$13-I$3)/($A$13-$A$3) -> 1.2475089 | J9: =J8+(J$13-J$3)/($A$13-$A$3) -> 1.2022382 | K9: =K8+(K$13-K$3)/($A$13-$A$3) -> 1.3762512 | M9: 2026 | N9: =N8+(N$13-N$3)/($A$13-$A$3) -> 1.2637284 | O9: =O8+(O$13-O$3)/($A$13-$A$3) -> 1.180817 | P9: =P8+(P$13-P$3)/($A$13-$A$3) -> 1.1258914 | Q9: =Q8+(Q$13-Q$3)/($A$13-$A$3) -> 1.3156491
A10: 2027 | B10: =B9+(B$13-B$3)/($A$13-$A$3) -> 1.0443272 | C10: =C9+(C$13-C$3)/($A$13-$A$3) -> 1.0597898 | D10: =D9+(D$13-D$3)/($A$13-$A$3) -> 1.0736364 | E10: =E9+(E$13-E$3)/($A$13-$A$3) -> 1.0463576 | G10: 2027 | H10: =H9+(H$13-H$3)/($A$13-$A$3) -> 1.3714496 | I10: =I9+(I$13-I$3)/($A$13-$A$3) -> 1.2887604 | J10: =J9+(J$13-J$3)/($A$13-$A$3) -> 1.2359446 | K10: =K9+(K$13-K$3)/($A$13-$A$3) -> 1.4389598 | M10: 2027 | N10: =N9+(N$13-N$3)/($A$13-$A$3) -> 1.3076831 | O10: =O9+(O$13-O$3)/($A$13-$A$3) -> 1.2109531 | P10: =P9+(P$13-P$3)/($A$13-$A$3) -> 1.1468733 | Q10: =Q9+(Q$13-Q$3)/($A$13-$A$3) -> 1.3682573
A11: 2028 | B11: =B10+(B$13-B$3)/($A$13-$A$3) -> 1.0506596 | C11: =C10+(C$13-C$3)/($A$13-$A$3) -> 1.0683311 | D11: =D10+(D$13-D$3)/($A$13-$A$3) -> 1.0841558 | E11: =E10+(E$13-E$3)/($A$13-$A$3) -> 1.0529801 | G11: 2028 | H11: =H10+(H$13-H$3)/($A$13-$A$3) -> 1.4245138 | I11: =I10+(I$13-I$3)/($A$13-$A$3) -> 1.3300119 | J11: =J10+(J$13-J$3)/($A$13-$A$3) -> 1.2696509 | K11: =K10+(K$13-K$3)/($A$13-$A$3) -> 1.5016683 | M11: 2028 | N11: =N10+(N$13-N$3)/($A$13-$A$3) -> 1.3516379 | O11: =O10+(O$13-O$3)/($A$13-$A$3) -> 1.2410893 | P11: =P10+(P$13-P$3)/($A$13-$A$3) -> 1.1678552 | Q11: =Q10+(Q$13-Q$3)/($A$13-$A$3) -> 1.4208654
A12: 2029 | B12: =B11+(B$13-B$3)/($A$13-$A$3) -> 1.0569921 | C12: =C11+(C$13-C$3)/($A$13-$A$3) -> 1.0768725 | D12: =D11+(D$13-D$3)/($A$13-$A$3) -> 1.0946753 | E12: =E11+(E$13-E$3)/($A$13-$A$3) -> 1.0596026 | G12: 2029 | H12: =H11+(H$13-H$3)/($A$13-$A$3) -> 1.4775781 | I12: =I11+(I$13-I$3)/($A$13-$A$3) -> 1.3712633 | J12: =J11+(J$13-J$3)/($A$13-$A$3) -> 1.3033573 | K12: =K11+(K$13-K$3)/($A$13-$A$3) -> 1.5643768 | M12: 2029 | N12: =N11+(N$13-N$3)/($A$13-$A$3) -> 1.3955926 | O12: =O11+(O$13-O$3)/($A$13-$A$3) -> 1.2712255 | P12: =P11+(P$13-P$3)/($A$13-$A$3) -> 1.1888371 | Q12: =Q11+(Q$13-Q$3)/($A$13-$A$3) -> 1.4734736
A13: 2030 | B13: =B$3*'SSP Scenarios'!I20/'SSP Scenarios'!I$19 -> 1.0633245 | C13: =C$3*'SSP Scenarios'!J20/'SSP Scenarios'!J$19 -> 1.0854139 | D13: =D$3*'SSP Scenarios'!K20/'SSP Scenarios'!K$19 -> 1.1051948 | E13: =E$3*'SSP Scenarios'!L20/'SSP Scenarios'!L$19 -> 1.0662252 | G13: 2030 | H13: =H$3 * 'SSP Scenarios'!N20/'SSP Scenarios'!N$19 -> 1.5306423 | I13: =I$3 * 'SSP Scenarios'!O20/'SSP Scenarios'!O$19 -> 1.4125148 | J13: =J$3 * 'SSP Scenarios'!P20/'SSP Scenarios'!P$19 -> 1.3370637 | K13: =K$3 * 'SSP Scenarios'!Q20/'SSP Scenarios'!Q$19 -> 1.6270854 | M13: 2030 | N13: =N$3 * 'SSP Scenarios'!S20/'SSP Scenarios'!S$19 -> 1.4395473 | O13: =O$3 * 'SSP Scenarios'!T20/'SSP Scenarios'!T$19 -> 1.3013616 | P13: =P$3 * 'SSP Scenarios'!U20/'SSP Scenarios'!U$19 -> 1.209819 | Q13: =Q$3 * 'SSP Scenarios'!V20/'SSP Scenarios'!V$19 -> 1.5260818
A14: 2040 | B14: =B$3*'SSP Scenarios'!I21/'SSP Scenarios'!I$19 -> 1.1068602 | C14: =C$3*'SSP Scenarios'!J21/'SSP Scenarios'!J$19 -> 1.1550591 | D14: =D$3*'SSP Scenarios'!K21/'SSP Scenarios'!K$19 -> 1.2025974 | E14: =E$3*'SSP Scenarios'!L21/'SSP Scenarios'!L$19 -> 1.1125828 | G14: 2040 | H14: =H$3 * 'SSP Scenarios'!N21/'SSP Scenarios'!N$19 -> 2.1921037 | I14: =I$3 * 'SSP Scenarios'!O21/'SSP Scenarios'!O$19 -> 1.8326414 | J14: =J$3 * 'SSP Scenarios'!P21/'SSP Scenarios'!P$19 -> 1.5746407 | K14: =K$3 * 'SSP Scenarios'!Q21/'SSP Scenarios'!Q$19 -> 2.5534838 | M14: 2040 | N14: =N$3 * 'SSP Scenarios'!S21/'SSP Scenarios'!S$19 -> 1.9805688 | O14: =O$3 * 'SSP Scenarios'!T21/'SSP Scenarios'!T$19 -> 1.5866245 | P14: =P$3 * 'SSP Scenarios'!U21/'SSP Scenarios'!U$19 -> 1.3093525 | Q14: =Q$3 * 'SSP Scenarios'!V21/'SSP Scenarios'!V$19 -> 2.2951986
A15: 2050 | B15: =B$3*'SSP Scenarios'!I22/'SSP Scenarios'!I$19 -> 1.1253298 | C15: =C$3*'SSP Scenarios'!J22/'SSP Scenarios'!J$19 -> 1.2049934 | D15: =D$3*'SSP Scenarios'!K22/'SSP Scenarios'!K$19 -> 1.2935065 | E15: =E$3*'SSP Scenarios'!L22/'SSP Scenarios'!L$19 -> 1.1364238 | G15: 2050 | H15: =H$3 * 'SSP Scenarios'!N22/'SSP Scenarios'!N$19 -> 2.8609311 | I15: =I$3 * 'SSP Scenarios'!O22/'SSP Scenarios'!O$19 -> 2.2755042 | J15: =J$3 * 'SSP Scenarios'!P22/'SSP Scenarios'!P$19 -> 1.7607803 | K15: =K$3 * 'SSP Scenarios'!Q22/'SSP Scenarios'!Q$19 -> 3.578999 | M15: 2050 | N15: =N$3 * 'SSP Scenarios'!S22/'SSP Scenarios'!S$19 -> 2.542436 | O15: =O$3 * 'SSP Scenarios'!T22/'SSP Scenarios'!T$19 -> 1.8883623 | P15: =P$3 * 'SSP Scenarios'!U22/'SSP Scenarios'!U$19 -> 1.3612143 | Q15: =Q$3 * 'SSP Scenarios'!V22/'SSP Scenarios'!V$19 -> 3.1494517
A16: 2060 | B16: =B$3*'SSP Scenarios'!I23/'SSP Scenarios'!I$19 -> 1.1200528 | C16: =C$3*'SSP Scenarios'!J23/'SSP Scenarios'!J$19 -> 1.2325887 | D16: =D$3*'SSP Scenarios'!K23/'SSP Scenarios'!K$19 -> 1.3727273 | E16: =E$3*'SSP Scenarios'!L23/'SSP Scenarios'!L$19 -> 1.1377483 | G16: 2060 | H16: =H$3 * 'SSP Scenarios'!N23/'SSP Scenarios'!N$19 -> 3.4992143 | I16: =I$3 * 'SSP Scenarios'!O23/'SSP Scenarios'!O$19 -> 2.7542507 | J16: =J$3 * 'SSP Scenarios'!P23/'SSP Scenarios'!P$19 -> 1.9241273 | K16: =K$3 * 'SSP Scenarios'!Q23/'SSP Scenarios'!Q$19 -> 4.6938175 | M16: 2060 | N16: =N$3 * 'SSP Scenarios'!S23/'SSP Scenarios'!S$19 -> 3.1242555 | O16: =O$3 * 'SSP Scenarios'!T23/'SSP Scenarios'!T$19 -> 2.2344843 | P16: =P$3 * 'SSP Scenarios'!U23/'SSP Scenarios'!U$19 -> 1.4016918 | Q16: =Q$3 * 'SSP Scenarios'!V23/'SSP Scenarios'!V$19 -> 4.125741
A17: 2070 | B17: =B$3*'SSP Scenarios'!I24/'SSP Scenarios'!I$19 -> 1.0949868 | C17: =C$3*'SSP Scenarios'!J24/'SSP Scenarios'!J$19 -> 1.2431012 | D17: =D$3*'SSP Scenarios'!K24/'SSP Scenarios'!K$19 -> 1.4441558 | E17: =E$3*'SSP Scenarios'!L24/'SSP Scenarios'!L$19 -> 1.1205298 | G17: 2070 | H17: =H$3 * 'SSP Scenarios'!N24/'SSP Scenarios'!N$19 -> 4.1179533 | I17: =I$3 * 'SSP Scenarios'!O24/'SSP Scenarios'!O$19 -> 3.3035785 | J17: =J$3 * 'SSP Scenarios'!P24/'SSP Scenarios'!P$19 -> 2.0952772 | K17: =K$3 * 'SSP Scenarios'!Q24/'SSP Scenarios'!Q$19 -> 5.9450442 | M17: 2070 | N17: =N$3 * 'SSP Scenarios'!S24/'SSP Scenarios'!S$19 -> 3.7608696 | O17: =O$3 * 'SSP Scenarios'!T24/'SSP Scenarios'!T$19 -> 2.6574889 | P17: =P$3 * 'SSP Scenarios'!U24/'SSP Scenarios'!U$19 -> 1.4508657 | Q17: =Q$3 * 'SSP Scenarios'!V24/'SSP Scenarios'!V$19 -> 5.3057943
A18: 2080 | B18: =B$3*'SSP Scenarios'!I25/'SSP Scenarios'!I$19 -> 1.0514512 | C18: =C$3*'SSP Scenarios'!J25/'SSP Scenarios'!J$19 -> 1.2365309 | D18: =D$3*'SSP Scenarios'!K25/'SSP Scenarios'!K$19 -> 1.5103896 | E18: =E$3*'SSP Scenarios'!L25/'SSP Scenarios'!L$19 -> 1.0860927 | G18: 2080 | H18: =H$3 * 'SSP Scenarios'!N25/'SSP Scenarios'!N$19 -> 4.6692202 | I18: =I$3 * 'SSP Scenarios'!O25/'SSP Scenarios'!O$19 -> 3.899565 | J18: =J$3 * 'SSP Scenarios'!P25/'SSP Scenarios'!P$19 -> 2.2725873 | K18: =K$3 * 'SSP Scenarios'!Q25/'SSP Scenarios'!Q$19 -> 7.2679097 | M18: 2080 | N18: =N$3 * 'SSP Scenarios'!S25/'SSP Scenarios'!S$19 -> 4.4409619 | O18: =O$3 * 'SSP Scenarios'!T25/'SSP Scenarios'!T$19 -> 3.1536147 | P18: =P$3 * 'SSP Scenarios'!U25/'SSP Scenarios'!U$19 -> 1.5046249 | Q18: =Q$3 * 'SSP Scenarios'!V25/'SSP Scenarios'!V$19 -> 6.692131
A19: 2090 | B19: =B$3*'SSP Scenarios'!I26/'SSP Scenarios'!I$19 -> 0.99076517 | C19: =C$3*'SSP Scenarios'!J26/'SSP Scenarios'!J$19 -> 1.2155059 | D19: =D$3*'SSP Scenarios'!K26/'SSP Scenarios'!K$19 -> 1.5753247 | E19: =E$3*'SSP Scenarios'!L26/'SSP Scenarios'!L$19 -> 1.0370861 | G19: 2090 | H19: =H$3 * 'SSP Scenarios'!N26/'SSP Scenarios'!N$19 -> 5.1549794 | I19: =I$3 * 'SSP Scenarios'!O26/'SSP Scenarios'!O$19 -> 4.5462633 | J19: =J$3 * 'SSP Scenarios'!P26/'SSP Scenarios'!P$19 -> 2.4649897 | K19: =K$3 * 'SSP Scenarios'!Q26/'SSP Scenarios'!Q$19 -> 8.6584887 | M19: 2090 | N19: =N$3 * 'SSP Scenarios'!S26/'SSP Scenarios'!S$19 -> 5.203246 | O19: =O$3 * 'SSP Scenarios'!T26/'SSP Scenarios'!T$19 -> 3.740164 | P19: =P$3 * 'SSP Scenarios'!U26/'SSP Scenarios'!U$19 -> 1.5647877 | Q19: =Q$3 * 'SSP Scenarios'!V26/'SSP Scenarios'!V$19 -> 8.3492146
A20: 2100 | B20: =B$3*'SSP Scenarios'!I27/'SSP Scenarios'!I$19 -> 0.9182058 | C20: =C$3*'SSP Scenarios'!J27/'SSP Scenarios'!J$19 -> 1.1865966 | D20: =D$3*'SSP Scenarios'!K27/'SSP Scenarios'!K$19 -> 1.638961 | E20: =E$3*'SSP Scenarios'!L27/'SSP Scenarios'!L$19 -> 0.97748344 | G20: 2100 | H20: =H$3 * 'SSP Scenarios'!N27/'SSP Scenarios'!N$19 -> 5.5528383 | I20: =I$3 * 'SSP Scenarios'!O27/'SSP Scenarios'!O$19 -> 5.2583037 | J20: =J$3 * 'SSP Scenarios'!P27/'SSP Scenarios'!P$19 -> 2.6852156 | K20: =K$3 * 'SSP Scenarios'!Q27/'SSP Scenarios'!Q$19 -> 10.117763 | M20: 2100 | N20: =N$3 * 'SSP Scenarios'!S27/'SSP Scenarios'!S$19 -> 6.0477963 | O20: =O$3 * 'SSP Scenarios'!T27/'SSP Scenarios'!T$19 -> 4.4313548 | P20: =P$3 * 'SSP Scenarios'!U27/'SSP Scenarios'!U$19 -> 1.6383904 | Q20: =Q$3 * 'SSP Scenarios'!V27/'SSP Scenarios'!V$19 -> 10.351289
A22: Data is based off the SSP Scenarios

Sheet Prediction Results
A1: Expected Damage of Minor Hazards for 2020 | F1: Expected damage of Medium Hazards for 2020 | K1: Expected damage of Major Hazards for 2020 | P1: Expected Property Damages for 2020
A2: Region | B2: Lower | C2: Upper | D2: Average | F2: Region | G2: Lower | H2: Upper | I2: Average | K2: Region | L2: Lower | M2: Upper | N2: Average | P2: Region | Q2: Lower | R2: Upper | S2: Average
A3: 1 | B3: 637301.5 | C3: 818859.4 | D3: 728080.4 | F3: 1 | G3: 4869045.7 | H3: 6607315.8 | I3: 5738180.8 | K3: 1 | L3: 7273781.9 | M3: 18772259 | N3: 13023021 | P3: 1 | Q3: =SUM($B3,$G3,$L3) -> 12780129 | R3: =SUM($C3,$H3,$M3) -> 26198434 | S3: =SUM(D3,I3,N3) -> 19489282
A4: 2 | B4: 957089.4 | C4: 1161032.8 | D4: 1059061.1 | F4: 2 | G4: 6708810.3 | H4: 8793270 | I4: 7751040.1 | K4: 2 | L4: 14309832 | M4: 27353015 | N4: 20831423 | P4: 2 | Q4: =SUM($B4,$G4,$L4) -> 21975731 | R4: =SUM($C4,$H4,$M4) -> 37307318 | S4: =SUM(D4,I4,N4) -> 29641525
A5: 3 | B5: 708746.3 | C5: 1075256.7 | D5: 892001.5 | F5: 3 | G5: 200408.99 | H5: 660668.2 | I5: 430538.62 | K5: 3 | L5: 0 | M5: 515764.13 | N5: 184239.4 | P5: 3 | Q5: =SUM($B5,$G5,$L5) -> 909155.29 | R5: =SUM($C5,$H5,$M5) -> 2251689 | S5: =SUM(D5,I5,N5) -> 1506779.5
A6: 4 | B6: 159923 | C6: 216557.3 | D6: 188240.2 | F6: 4 | G6: 89789.32 | H6: 287276.5 | I6: 188532.92 | K6: 4 | L6: 4214.575 | M6: 33540.63 | N6: 18877.6 | P6: 4 | Q6: =SUM($B6,$G6,$L6) -> 253926.9 | R6: =SUM($C6,$H6,$M6) -> 537374.43 | S6: =SUM(D6,I6,N6) -> 395650.72
A7: 5 | B7: 110462.8 | C7: 157262.9 | D7: 133862.8 | F7: 5 | G7: 54646.88 | H7: 124653.1 | I7: 89650.01 | K7: 5 | L7: 2398.027 | M7: 279181.07 | N7: 140789.5 | P7: 5 | Q7: =SUM($B7,$G7,$L7) -> 167507.71 | R7: =SUM($C7,$H7,$M7) -> 561097.07 | S7: =SUM(D7,I7,N7) -> 364302.31
A8: 6 | B8: 152230.8 | C8: 227168 | D8: 189699.4 | F8: 6 | G8: 206918.18 | H8: 515738.9 | I8: 361328.54 | K8: 6 | L8: 0 | M8: 241269.43 | N8: 107315.4 | P8: 6 | Q8: =SUM($B8,$G8,$L8) -> 359148.98 | R8: =SUM($C8,$H8,$M8) -> 984176.33 | S8: =SUM(D8,I8,N8) -> 658343.34
A10: Expected Frequency of Minor Hazards for 2020 | F10: Expected Frequency of Medium Hazards for 2020 | K10: Expected Frequency of Major Hazards for 2020
A11: Region | B11: Lower | C11: Upper | D11: Average | F11: Region | G11: Lower | H11: Upper | I11: Average | K11: Region | L11: Lower | M11: Upper | N11: Average
A12: 1 | B12: 4.753026 | C12: 5.908667 | D12: 5.330847 | F12: 1 | G12: 2.8920706 | H12: 3.7699461 | I12: 3.3310084 | K12: 1 | L12: 0.63511822 | M12: 1.2511574 | N12: 0.94313779
A13: 2 | B13: 17.033253 | C13: 19.260826 | D13: 18.147039 | F13: 2 | G13: 3.7669012 | H13: 4.7119345 | I13: 4.2394179 | K13: 2 | L13: 0.91317767 | M13: 1.6247976 | N13: 1.2689876
A14: 3 | B14: 21.49466 | C14: 24.505776 | D14: 23.000218 | F14: 3 | G14: 0.18268762 | H14: 0.7503435 | I14: 0.4665156 | K14: 3 | L14: 2.728054e-06 | M14: 0.098897712 | N14: 0.034936917
A15: 4 | B15: 6.274451 | C15: 7.146808 | D15: 6.71063 | F15: 4 | G15: 0.09112506 | H15: 0.2661026 | I15: 0.1786138 | K15: 4 | L15: 0.0003972618 | M15: 0.004657574 | N15: 0.002527418
A16: 5 | B16: 5.146812 | C16: 5.795913 | D16: 5.471363 | F16: 5 | G16: 0.04384714 | H16: 0.1051717 | I16: 0.0745094 | K16: 5 | L16: 0.0021685743 | M16: 0.010526101 | N16: 0.006347338
A17: 6 | B17: 3.310586 | C17: 4.162998 | D17: 3.736792 | F17: 6 | G17: 0.18766701 | H17: 0.3840542 | I17: 0.2858606 | K17: 6 | L17: 0 | M17: 0.020822799 | N17: 0.009616051
A19: Expected Severity of Minor Hazards for 2020 | F19: Expected Severity of Medium Hazards for 2020 | K19: Expected Severity of Major Hazards for 2020
A20: Region | B20: Lower | C20: Upper | D20: Average | F20: Region | G20: Lower | H20: Upper | I20: Average | K20: Region | L20: Lower | M20: Upper | N20: Average
A21: 1 | B21: 115378.04 | C21: 128504.4 | D21: 121941.22 | F21: 1 | G21: 1618092 | H21: 1760330 | I21: 1689211 | K21: 1 | L21: 13474916 | M21: 17761482 | N21: 15618199
A22: 2 | B22: 62700.04 | C22: 71005.1 | D22: 66852.57 | F22: 2 | G22: 1722249 | H22: 1879415 | I22: 1800832 | K22: 2 | L22: 21894899 | M22: 32170861 | N22: 27032880
A23: 3 | B23: 19922.48 | C23: 24836.39 | D23: 22379.44 | F23: 3 | G23: 1151122 | H23: 1372402 | I23: 1261762 | K23: 3 | L23: 6836080 | M23: 7683538 | N23: 7259809
A24: 4 | B24: 22788.4 | C24: 28557.58 | D24: 25672.99 | F24: 4 | G24: 1175298 | H24: 1415357 | I24: 1295328 | K24: 4 | L24: 9431026 | M24: 12029764 | N24: 10730395
A25: 5 | B25: 24317.79 | C25: 30150.38 | D25: 27234.08 | F25: 5 | G25: 1289242 | H25: 1592576 | I25: 1440909 | K25: 5 | L25: 12965270 | M25: 19099580 | N25: 16032425
A26: 6 | B26: 35287.4 | C26: 42355.05 | D26: 38821.23 | F26: 6 | G26: 1223742 | H26: 1473160 | I26: 1348451 | K26: 6 | L26: 8927984 | M26: 10621326 | N26: 9774655

Sheet Prediction Results (Transposed)
A1: Expected Property Damages for 2020 | I1: % of Damage for each hazard severity
A2: {=TRANSPOSE('Prediction Results'!$P$2:$S$8)} -> Region | B2: 1 | C2: 2 | D2: 3 | E2: 4 | F2: 5 | G2: 6 | I2: Region | J2: 1 | K2: 2 | L2: 3 | M2: 4 | N2: 5 | O2: 6
A3: Lower | B3: 12780129 | C3: 21975731 | D3: 909155.29 | E3: 253926.9 | F3: 167507.71 | G3: 359148.98 | I3: Minor | J3: =IF(Costing!$B$4 = "lower", B9/B$3, IF(Costing!$B$4 = "upper", B10/B$4, IF(Costing!$B$4 = "average", B11/B$5, "Invalid"))) -> 0.031256043 | K3: =IF(Costing!$B$4 = "lower", C9/C$3, IF(Costing!$B$4 = "upper", C10/C$4, IF(Costing!$B$4 = "average", C11/C$5, "Invalid"))) -> 0.031120779 | L3: =IF(Costing!$B$4 = "lower", D9/D$3, IF(Costing!$B$4 = "upper", D10/D$4, IF(Costing!$B$4 = "average", D11/D$5, "Invalid"))) -> 0.47753339 | M3: =IF(Costing!$B$4 = "lower", E9/E$3, IF(Costing!$B$4 = "upper", E10/E$4, IF(Costing!$B$4 = "average", E11/E$5, "Invalid"))) -> 0.40299145 | N3: =IF(Costing!$B$4 = "lower", F9/F$3, IF(Costing!$B$4 = "upper", F10/F$4, IF(Costing!$B$4 = "average", F11/F$5, "Invalid"))) -> 0.28027753 | O3: =IF(Costing!$B$4 = "lower", G9/G$3, IF(Costing!$B$4 = "upper", G10/G$4, IF(Costing!$B$4 = "average", G11/G$5, "Invalid"))) -> 0.23082043
A4: Upper | B4: 26198434 | C4: 37307318 | D4: 2251689 | E4: 537374.43 | F4: 561097.07 | G4: 984176.33 | I4: Medium | J4: =IF(Costing!$B$4 = "lower", B15/B$3, IF(Costing!$B$4 = "upper", B16/B$4, IF(Costing!$B$4 = "average", B17/B$5, "Invalid"))) -> 0.2522027 | K4: =IF(Costing!$B$4 = "lower", C15/C$3, IF(Costing!$B$4 = "upper", C16/C$4, IF(Costing!$B$4 = "average", C17/C$5, "Invalid"))) -> 0.23569826 | L4: =IF(Costing!$B$4 = "lower", D15/D$3, IF(Costing!$B$4 = "upper", D16/D$4, IF(Costing!$B$4 = "average", D17/D$5, "Invalid"))) -> 0.29341005 | M4: =IF(Costing!$B$4 = "lower", E15/E$3, IF(Costing!$B$4 = "upper", E16/E$4, IF(Costing!$B$4 = "average", E17/E$5, "Invalid"))) -> 0.5345928 | N4: =IF(Costing!$B$4 = "lower", F15/F$3, IF(Costing!$B$4 = "upper", F16/F$4, IF(Costing!$B$4 = "average", F17/F$5, "Invalid"))) -> 0.2221596 | O4: =IF(Costing!$B$4 = "lower", G15/G$3, IF(Costing!$B$4 = "upper", G16/G$4, IF(Costing!$B$4 = "average", G17/G$5, "Invalid"))) -> 0.52403099
A5: Average | B5: 19489282 | C5: 29641525 | D5: 1506779.5 | E5: 395650.72 | F5: 364302.31 | G5: 658343.34 | I5: Major | J5: =IF(Costing!$B$4 = "lower", B21/B$3, IF(Costing!$B$4 = "upper", B22/B$4, IF(Costing!$B$4 = "average", B23/B$5, "Invalid"))) -> 0.71654126 | K5: =IF(Costing!$B$4 = "lower", C21/C$3, IF(Costing!$B$4 = "upper", C22/C$4, IF(Costing!$B$4 = "average", C23/C$5, "Invalid"))) -> 0.73318096 | L5: =IF(Costing!$B$4 = "lower", D21/D$3, IF(Costing!$B$4 = "upper", D22/D$4, IF(Costing!$B$4 = "average", D23/D$5, "Invalid"))) -> 0.22905655 | M5: =IF(Costing!$B$4 = "lower", E21/E$3, IF(Costing!$B$4 = "upper", E22/E$4, IF(Costing!$B$4 = "average", E23/E$5, "Invalid"))) -> 0.062415754 | N5: =IF(Costing!$B$4 = "lower", F21/F$3, IF(Costing!$B$4 = "upper", F22/F$4, IF(Costing!$B$4 = "average", F23/F$5, "Invalid"))) -> 0.49756287 | O5: =IF(Costing!$B$4 = "lower", G21/G$3, IF(Costing!$B$4 = "upper", G22/G$4, IF(Costing!$B$4 = "average", G23/G$5, "Invalid"))) -> 0.24514858
A7: Expected Minor Hazard Damages for 2020
A8: {=TRANSPOSE('Prediction Results'!$A$2:$D$8)} -> Region | B8: 1 | C8: 2 | D8: 3 | E8: 4 | F8: 5 | G8: 6
A9: Lower | B9: 637301.5 | C9: 957089.4 | D9: 708746.3 | E9: 159923 | F9: 110462.8 | G9: 152230.8
A10: Upper | B10: 818859.4 | C10: 1161032.8 | D10: 1075256.7 | E10: 216557.3 | F10: 157262.9 | G10: 227168
A11: Average | B11: 728080.4 | C11: 1059061.1 | D11: 892001.5 | E11: 188240.2 | F11: 133862.8 | G11: 189699.4
A13: Expected Medium Hazard Damages for 2020
A14: {=TRANSPOSE('Prediction Results'!$F$2:$I$8)} -> Region | B14: 1 | C14: 2 | D14: 3 | E14: 4 | F14: 5 | G14: 6
A15: Lower | B15: 4869045.7 | C15: 6708810.3 | D15: 200408.99 | E15: 89789.32 | F15: 54646.88 | G15: 206918.18
A16: Upper | B16: 6607315.8 | C16: 8793270 | D16: 660668.2 | E16: 287276.5 | F16: 124653.1 | G16: 515738.9
A17: Average | B17: 5738180.8 | C17: 7751040.1 | D17: 430538.62 | E17: 188532.92 | F17: 89650.01 | G17: 361328.54
A19: Expected Major Hazard Damages for 2020
A20: {=TRANSPOSE('Prediction Results'!$K$2:$N$8)} -> Region | B20: 1 | C20: 2 | D20: 3 | E20: 4 | F20: 5 | G20: 6
A21: Lower | B21: 7273781.9 | C21: 14309832 | D21: 0 | E21: 4214.575 | F21: 2398.027 | G21: 0
A22: Upper | B22: 18772259 | C22: 27353015 | D22: 515764.13 | E22: 33540.63 | F22: 279181.07 | G22: 241269.43
A23: Average | B23: 13023021 | C23: 20831423 | D23: 184239.4 | E23: 18877.6 | F23: 140789.5 | G23: 107315.4
A80: =Costing!D23*0.013*('Prediction Results (Transposed)'!J3 + 'Prediction Results (Transposed)'!J4 + 'Prediction Results (Transposed)'!J5) -> 81983.304

Sheet Costing
C1: SSP1 | K1: SSP2 | S1: SSP3 | AA1: SSP5
D2: Region 1 | E2: Region 2 | F2: Region 3 | G2: Region 4 | H2: Region 5 | I2: Region 6 | L2: Region 1 | M2: Region 2 | N2: Region 3 | O2: Region 4 | P2: Region 5 | Q2: Region 6 | T2: Region 1 | U2: Region 2 | V2: Region 3 | W2: Region 4 | X2: Region 5 | Y2: Region 6 | AB2: Region 1 | AC2: Region 2 | AD2: Region 3 | AE2: Region 4 | AF2: Region 5 | AG2: Region 6
A3: Input Table | C3: Year | D3: Expected Property Damage | K3: Year | L3: Expected Property Damage | S3: Year | T3: Expected Property Damage | AA3: Year | AB3: Expected Property Damage
