Workbook

Sheet Demographic-Economic
H2: Copyright © 2023 by the Society of Actuaries Research Institute. All rights reserved.
B6: Historical Storslysia Census and Economic Data by Region
C8: Region 1 | D8: Region 2 | E8: Region 3 | F8: Region 4 | G8: Region 5 | H8: Region 6
B9: Census, July 1, 2021 | C9: 6406008 | D9: 4386948 | E9: 5019684 | F9: 995544 | G9: 1257096 | H9: 313836
B10: Census, July 1, 2020 | C10: 6306408 | D10: 4212348 | E10: 4993764 | F10: 1010676 | G10: 1266672 | H10: 307884
B11: Census, July 1, 2019 | C11: 5414700 | D11: 3231492 | E11: 4614048 | F11: 1110012 | G11: 1289472 | H11: 323820
B12: Percent over age 18 | C12: 0.772 | D12: 0.827 | E12: 0.785 | F12: 0.781 | G12: 0.76 | H12: 0.827
B13: Percent age 65 and older | C13: 0.165 | D13: 0.261 | E13: 0.137 | F13: 0.209 | G13: 0.172 | H13: 0.2
B14: Housing Units | C14: 2791896 | D14: 2523732 | E14: 2212536 | F14: 496548 | G14: 566592 | H14: 135480 | J14: (assume this is 2020 data)
B15: Owner-Occupied Housing Units | C15: 1904073 | D15: 1862514 | E15: 1323096 | F15: 333680 | G15: 365451 | H15: 102693
B16: Median Value of Owner-Occupied Housing Units | C16: Ꝕ 260,765 | D16: Ꝕ 248,083 | E16: Ꝕ 221,267 | F16: Ꝕ 121,135 | G16: Ꝕ 158,255 | H16: Ꝕ 175,164
B17: Median Monthly Homeowner Housing Costs | C17: Ꝕ 1,726 | D17: Ꝕ 1,644 | E17: Ꝕ 1,731 | F17: Ꝕ 1,474 | G17: Ꝕ 1,438 | H17: Ꝕ 1,486
B18: Median Rent (Ꝕ) | C18: 1260 | D18: 1287 | E18: 1318 | F18: 923 | G18: 1068 | H18: 882
B19: Building Permits, 2021 | C19: 95568 | D19: 83640 | E19: 39156 | F19: 1080 | G19: 4656 | H19: 2328
B20: Growth in the Number of Housing Units | E20: =E19/E14+1 -> 1.0176973 | F20: =F19/F14+1 -> 1.002175 | G20: =G19/G14+1 -> 1.0082176 | H20: =H19/H14+1 -> 1.0171833 | J20: Building Permits/Housing Units +1
B21: Labor Force (percent over age 16 and older), 2016-2020 | C21: 0.648 | D21: 0.553 | E21: 0.627 | F21: 0.549 | G21: 0.557 | H21: 0.51
B22: Total accommodation and food services sales, 2017 (Ꝕ1,000) | C22: 22342094 | D22: 36406400 | E22: 17508375 | F22: 2774258 | G22: 2611585 | H22: 151132
B23: Total health care and social assistance receipts/revenue, 2017 (Ꝕ1,000) | C23: 51556220 | D23: 26864638 | E23: 70145543 | F23: 6658061 | G23: 9541905 | H23: 697773
B24: Total transportation and warehousing receipts/revenue, 2017 (Ꝕ1,000) | C24: 13500228 | D24: 2862506 | E24: 3929251 | F24: 2234577 | G24: 2307892 | H24: =K24 -> 199078.17 | K24: =SUM(C24:G24)*(1+'Inflation-Interest'!C65)*(1+'Inflation-Interest'!C66)*(1+'Inflation-Interest'!C67)*'Demographic-Economic'!H38/SUM('Demographic-Economic'!C38:G38) -> 199078.17 | L24: <- prediction for region 6 transportation cost in 2020
B25: Total retail sales, 2017 (Ꝕ1,000) | C25: 120644546 | D25: 104661514 | E25: 86911348 | F25: 16147988 | G25: 17600539 | H25: 2241932
B26: Total retail sales per capita, 2017 | C26: Ꝕ 19,811 | D26: Ꝕ 26,171 | E26: Ꝕ 17,558 | F26: Ꝕ 15,350 | G26: Ꝕ 13,758 | H26: Ꝕ 6,959
B27: Households, 2016-2020 | C27: 2376180 | D27: 1634628 | E27: 1865736 | F27: 403548 | G27: 500448 | H27: 110052
B28: Vacant Housing Units | C28: =C14-C27 -> 415716 | D28: =D14-D27 -> 889104 | E28: =E14-E27 -> 346800 | F28: =F14-F27 -> 93000 | G28: =G14-G27 -> 66144 | H28: =H14-H27 -> 25428
B29: Persons per Household, 2016-2020 | C29: 2.55 | D29: 2.49 | E29: 2.47 | F29: 2.5 | G29: 2.5 | H29: 2.65 | J29: (assume that this stays constant throughout time)
B30: Median Household Income (Ꝕ) | C30: 82459 | D30: 68123 | E30: 71916 | F30: 48615 | G30: 61518 | H30: 69340 | J30: (assume yearly, assume it’s 2020)
B31: Prior Year Per Capita Income | C31: Ꝕ 45,482 | D31: Ꝕ 38,381 | E31: Ꝕ 40,937 | F31: Ꝕ 28,186 | G31: Ꝕ 32,418 | H31: Ꝕ 35,948
B32: Persons in poverty, percent | C32: 0.121 | D32: 0.128 | E32: 0.16 | F32: 0.191 | G32: 0.205 | H32: 0.168
B33: Total Number of Employers, 2020 | C33: 170172 | D33: 113688 | E33: 110220 | F33: 18924 | G33: 21132 | H33: 3888
B34: Total Employment, 2020 | C34: 2990424 | D34: 1412112 | E34: 1941528 | F34: 284904 | G34: 388428 | H34: 65676
B35: Total Annual Payroll (Ꝕ1,000) | C35: 186551503 | D35: 60187999 | E35: 116972082 | F35: 14470878 | G35: 20694659 | H35: 2989576
B36: Population per hectare | C36: 2.58 | D36: 1.19 | E36: 2.12 | F36: 0.29 | G36: 0.61 | H36: 0.19
B37: Land area in hectares | C37: 2442659 | D37: 3522311 | E37: 2353615 | F37: 3438613 | G37: 2067059 | H37: 1556199
B38: GDP, 2020 (Ꝕ1,000 ) | C38: 531771287 | D38: 222153795 | E38: 417708522 | F38: 45815957 | G38: 69643447 | H38: 9845914
B39: Real GDP, 2020 (Ꝕ1,000 ) | C39: =C38/(1+'Inflation-Interest'!$C$66) -> 5.2288229e+08 | D39: =D38/(1+'Inflation-Interest'!$C$66) -> 2.1844031e+08 | E39: =E38/(1+'Inflation-Interest'!$C$66) -> 4.1072618e+08 | F39: =F38/(1+'Inflation-Interest'!$C$66) -> 45050105 | G39: =G38/(1+'Inflation-Interest'!$C$66) -> 68479299 | H39: =H38/(1+'Inflation-Interest'!$C$66) -> 9681331.4
B40: GDP, 2019 (Ꝕ1,000 ) | C40: 534828123 | D40: 223457321 | E40: 414066160 | F40: 46354925 | G40: 68360180 | H40: 9766147
B41: Real GDP, 2019 (Ꝕ1,000 ) | C41: =C40/(1+'Inflation-Interest'!$C$65) -> 5.2372515e+08 | D41: =D40/(1+'Inflation-Interest'!$C$65) -> 2.1881837e+08 | E41: =E40/(1+'Inflation-Interest'!$C$65) -> 4.0547019e+08 | F41: =F40/(1+'Inflation-Interest'!$C$65) -> 45392602 | G41: =G40/(1+'Inflation-Interest'!$C$65) -> 66941030 | H41: =H40/(1+'Inflation-Interest'!$C$65) -> 9563402.9
B42: Temporary housing cost with disaster (per person per month) (Ꝕ) | C42: 1920 | D42: 1829 | E42: 1925 | F42: 1639 | G42: 1599 | H42: 1653
B43: Property Value distribution <Ꝕ50K | C43: 0.043 | D43: 0.0633 | E43: 0.0356 | F43: 0.1882 | G43: 0.0996 | H43: 0.0759 | I43: =50000 -> 50000
B44: Property Value distribution Ꝕ50K-Ꝕ99K | C44: 0.0459 | D44: 0.0537 | E44: 0.0623 | F44: 0.1888 | G44: 0.1397 | H44: 0.1579 | I44: =(50000+99000)/2 -> 74500
B45: Property Value distribution Ꝕ100K-Ꝕ149K | C45: 0.0695 | D45: 0.0693 | E45: 0.1123 | F45: 0.1578 | G45: 0.1891 | H45: 0.1336 | I45: =(100000+149000)/2 -> 124500
...

Sheet Inflation-Interest
J2: Copyright © 2023 by the Society of Actuaries Research Institute. All rights reserved.
B6: Historical Storslysia Inflation and Interest Rates
B8: Year | C8: Inflation | D8: delta_Inflation | E8: Government Overnight Bank Lending Rate | F8: 1-yr risk free rate | G8: 10-yr risk free rate | I8: Legend
B9: 1962 | C9: 0.0213 | E9: 0.0307 | F9: 0.0351 | G9: 0.0446 | I9: Inflation | J9: Average annual rate for the year
B10: 1963 | C10: 0.0201 | D10: =C10-C9 -> -0.0012 | E10: 0.0358 | F10: 0.038 | G10: 0.0452 | I10: Government overnight bank lending rate | J10: Average annual rate for the year
B11: 1964 | C11: 0.0205 | D11: =C11-C10 -> 0.0004 | E11: 0.0394 | F11: 0.0435 | G11: 0.0473 | I11: 1-yr risk free rate | J11: Average annual rate for the year
B12: 1965 | C12: 0.0254 | D12: =C12-C11 -> 0.0049 | E12: 0.0458 | F12: 0.0468 | G12: 0.0484 | I12: 10-yr risk free rate | J12: Average annual rate for the year
B13: 1966 | C13: 0.033 | D13: =C13-C12 -> 0.0076 | E13: 0.057 | F13: 0.0587 | G13: 0.0556
B14: 1967 | C14: 0.0274 | D14: =C14-C13 -> -0.0056 | E14: 0.0474 | F14: 0.055 | G14: 0.0572
B15: 1968 | C15: 0.0348 | D15: =C15-C14 -> 0.0074 | E15: 0.0635 | F15: 0.0641 | G15: 0.0636
B16: 1969 | C16: 0.0406 | D16: =C16-C15 -> 0.0058 | E16: 0.091 | F16: 0.0802 | G16: 0.0751
B17: 1970 | C17: 0.0504 | D17: =C17-C16 -> 0.0098 | E17: 0.0803 | F17: 0.0777 | G17: 0.0828
B18: 1971 | C18: 0.0472 | D18: =C18-C17 -> -0.0032 | E18: 0.0527 | F18: 0.0552 | G18: 0.0694
B19: 1972 | C19: 0.0441 | D19: =C19-C18 -> -0.0031 | E19: 0.05 | F19: 0.0559 | G19: 0.0699
B20: 1973 | C20: 0.0676 | D20: =C20-C19 -> 0.0235 | E20: 0.0979 | F20: 0.0824 | G20: 0.0771
B21: 1974 | C21: 0.1086 | D21: =C21-C20 -> 0.041 | E21: 0.118 | F21: 0.0923 | G21: 0.0851
B22: 1975 | C22: 0.089 | D22: =C22-C21 -> -0.0196 | E22: 0.0656 | F22: 0.0763 | G22: 0.0899
B23: 1976 | C23: 0.0643 | D23: =C23-C22 -> -0.0247 | E23: 0.0569 | F23: 0.0663 | G23: 0.0857
B24: 1977 | C24: 0.0686 | D24: =C24-C23 -> 0.0043 | E24: 0.0624 | F24: 0.0685 | G24: 0.0835
... B33: 1986 | C33: 0.02 | D33: =C33-C32 -> -0.0177 | E33: 0.077 | F33: 0.0727 | G33: 0.0863
B34: 1987 | C34: 0.0313 | D34: =C34-C33 -> 0.0113 | E34: =AVERAGE(E33, E35) -> 0.0811 | F34: 0.0762 | G34: 0.0944
B35: 1988 | C35: 0.0368 | D35: =C35-C34 -> 0.0055 | E35: 0.0852 | F35: 0.0861 | G35: 0.0995
B36: 1989 | C36: 0.0483 | D36: =C36-C35 -> 0.0115 | E36: 0.1038 | F36: 0.096 | G36: 0.0955
B37: 1990 | C37: 0.051 | D37: =C37-C36 -> 0.0027 | E37: 0.0913 | F37: 0.0887 | G37: 0.0962
B38: 1991 | C38: 0.0453 | D38: =C38-C37 -> -0.0057 | E38: 0.0646 | F38: 0.066 | G38: 0.0885
B39: 1992 | C39: 0.0426 | D39: =C39-C38 -> -0.0027 | E39: 0.0404 | F39: 0.044 | G39: 0.0789
B40: 1993 | C40: 0.0374 | D40: =C40-C39 -> -0.0052 | E40: 0.0346 | F40: 0.0389 | G40: 0.0661
B41: 1994 | C41: 0.0319 | D41: =C41-C40 -> -0.0055 | E41: 0.0477 | F41: 0.06 | G41: 0.0798
B42: 1995 | C42: 0.0304 | D42: =C42-C41 -> -0.0015 | E42: 0.066 | F42: 0.067 | G42: 0.074
B43: 1996 | C43: 0.0283 | D43: =C43-C42 -> -0.0021 | E43: 0.0601 | F43: 0.0622 | G43: 0.0726
B44: 1997 | C44: 0.0247 | D44: =C44-C43 -> -0.0036 | E44: 0.0619 | F44: 0.0635 | G44: 0.0716
B45: 1998 | C45: 0.0166 | D45: =C45-C44 -> -0.0081 | E45: 0.0605 | F45: 0.057 | G45: 0.0593
B46: 1999 | C46: 0.0189 | D46: =C46-C45 -> 0.0023 | E46: 0.0563 | F46: 0.0573 | G46: 0.0636
... B49: 2002 | C49: 0.0178 | D49: =C49-C48 -> -0.0104 | E49: 0.0192 | F49: 0.0228 | G49: 0.0521
B50: 2003 | C50: =AVERAGE(C49, C51) -> 0.02085 | D50: =C50-C49 -> 0.00305 | E50: 0.0131 | F50: 0.0143 | G50: 0.0454
B51: 2004 | C51: 0.0239 | D51: =C51-C50 -> 0.00305 | E51: 0.0156 | F51: 0.0215 | G51: 0.0482
B52: 2005 | C52: 0.0281 | D52: =C52-C51 -> 0.0042 | E52: 0.0364 | F52: 0.041 | G52: 0.0484
B53: 2006 | C53: 0.0278 | D53: =C53-C52 -> -0.0003 | E53: 0.056 | F53: 0.0557 | G53: 0.0541
B54: 2007 | C54: 0.0266 | D54: =C54-C53 -> -0.0012 | E54: 0.0567 | F54: 0.0511 | G54: 0.0523
B55: 2008 | C55: 0.037 | D55: =C55-C54 -> 0.0104 | E55: 0.0221 | F55: 0.0209 | G55: 0.0414
...

Sheet SSP Scenarios
B2: Four of the IPCC's SSP Scenarios for Future Atmospheric CO2 Concentrations, Worldwide Population, and GDP
B3: The scenarios produced by the Intergovernmental Panel on Climate Change (IPCC) are referred to as Shared Socioeconomic Pathways (SSPs). The SSPs reflect assumptions about population growth, economic growth, the use of sustainable energy sources versus fossil fuels, as well as other factors which, collectively, lead to a prediction for the trajectory of Green House Gas (GHG) emissions and the resulting atmospheric Carbon Dioxide (CO2) concentrations.
B6: https://ourworldindata.org/explorers/ipcc-scenarios
B8: Scenarios
B9: SSP1‒2.6 | D9: Low Emissions
B10: SSP2‒3.4 | D10: Medium Emissions
B11: SSP3‒6.0 | D11: High Emissions
B12: SSP5‒Baseline | D12: Very High Emissions
D14: Atmospheric CO2 in Parts per Million | I14: World Population (Billions) | N14: Worldwide GDP (Trillions $US) | S14: GDP Per Capita ($US)
D15: SSP1‒ 2.6 | E15: SSP2‒ 3.4 | F15: SSP3‒ 6.0 | G15: SSP5‒ Baseline | I15: SSP1‒ 2.6 | J15: SSP2‒ 3.4 | K15: SSP3‒ 6.0 | L15: SSP5‒ Baseline | N15: SSP1‒ 2.6 | O15: SSP2‒ 3.4 | P15: SSP3‒ 6.0 | Q15: SSP5‒ Baseline | S15: SSP1‒ 2.6 | T15: SSP2‒ 3.4 | U15: SSP3‒ 6.0 | V15: SSP5‒ Baseline
B17: 2005 | D17: 379.85 | E17: 379.85 | F17: 379.85 | G17: 379.85 | I17: 6.53 | J17: 6.5 | K17: 6.49 | L17: 6.51 | N17: 57.41 | O17: 56.53 | P17: 54.73 | Q17: 56.69 | S17: 8791 | T17: 8697 | U17: 8433 | V17: 8708
B18: 2010 | D18: 390.51 | E18: 390.51 | F18: 390.51 | G18: 390.51 | I18: 6.92 | J18: 6.87 | K18: 6.88 | L18: 6.89 | N18: 68.46 | O18: 67.52 | P18: 64.81 | Q18: 67.57 | S18: 9893 | T18: 9828 | U18: 9420 | V18: 9806
B19: 2020 | D19: 414.55 | E19: 414.44 | F19: 417.07 | G19: 417.25 | I19: 7.58 | J19: 7.61 | K19: 7.7 | L19: 7.55 | N19: 101.82 | O19: 101.16 | P19: 97.4 | Q19: 101.9 | S19: 13432 | T19: 13293 | U19: 12649 | V19: 13496
B20: 2021 | D20: =(D$29-D$19)/10+D19 -> 416.749 | E20: =(E$29-E$19)/10+E19 -> 416.924 | F20: =(F$29-F$19)/10+F19 -> 420.218 | G20: =(G$29-G$19)/10+G19 -> 420.802 | I20: =(I$29-I$19)/10+I19 -> 7.628 | J20: =(J$29-J$19)/10+J19 -> 7.675 | K20: =(K$29-K$19)/10+K19 -> 7.781 | L20: =(L$29-L$19)/10+L19 -> 7.6 | N20: =(N$29-N$19)/10+N19 -> 107.223 | O20: =(O$29-O$19)/10+O19 -> 105.333 | P20: =(P$29-P$19)/10+P19 -> 100.683 | Q20: =(Q$29-Q$19)/10+Q19 -> 108.29 | S20: =(S$29-S$19)/10+S19 -> 14022.4 | T20: =(T$29-T$19)/10+T19 -> 13693.6 | U20: =(U$29-U$19)/10+U19 -> 12914.4 | V20: =(V$29-V$19)/10+V19 -> 14206
B21: 2022 | D21: =(D$29-D$19)/10+D20 -> 418.948 | E21: =(E$29-E$19)/10+E20 -> 419.408 | F21: =(F$29-F$19)/10+F20 -> 423.366 | G21: =(G$29-G$19)/10+G20 -> 424.354 | I21: =(I$29-I$19)/10+I20 -> 7.676 | J21: =(J$29-J$19)/10+J20 -> 7.74 | K21: =(K$29-K$19)/10+K20 -> 7.862 | L21: =(L$29-L$19)/10+L20 -> 7.65 | N21: =(N$29-N$19)/10+N20 -> 112.626 | O21: =(O$29-O$19)/10+O20 -> 109.506 | P21: =(P$29-P$19)/10+P20 -> 103.966 | Q21: =(Q$29-Q$19)/10+Q20 -> 114.68 | S21: =(S$29-S$19)/10+S20 -> 14612.8 | T21: =(T$29-T$19)/10+T20 -> 14094.2 | U21: =(U$29-U$19)/10+U20 -> 13179.8 | V21: =(V$29-V$19)/10+V20 -> 14916
B22: 2023 | D22: =(D$29-D$19)/10+D21 -> 421.147 | E22: =(E$29-E$19)/10+E21 -> 421.892 | F22: =(F$29-F$19)/10+F21 -> 426.514 | G22: =(G$29-G$19)/10+G21 -> 427.906 | I22: =(I$29-I$19)/10+I21 -> 7.724 | J22: =(J$29-J$19)/10+J21 -> 7.805 | K22: =(K$29-K$19)/10+K21 -> 7.943 | L22: =(L$29-L$19)/10+L21 -> 7.7 | N22: =(N$29-N$19)/10+N21 -> 118.029 | O22: =(O$29-O$19)/10+O21 -> 113.679 | P22: =(P$29-P$19)/10+P21 -> 107.249 | Q22: =(Q$29-Q$19)/10+Q21 -> 121.07 | S22: =(S$29-S$19)/10+S21 -> 15203.2 | T22: =(T$29-T$19)/10+T21 -> 14494.8 | U22: =(U$29-U$19)/10+U21 -> 13445.2 | V22: =(V$29-V$19)/10+V21 -> 15626
B23: 2024 | D23: =(D$29-D$19)/10+D22 -> 423.346 | E23: =(E$29-E$19)/10+E22 -> 424.376 | F23: =(F$29-F$19)/10+F22 -> 429.662 | G23: =(G$29-G$19)/10+G22 -> 431.458 | I23: =(I$29-I$19)/10+I22 -> 7.772 | J23: =(J$29-J$19)/10+J22 -> 7.87 | K23: =(K$29-K$19)/10+K22 -> 8.024 | L23: =(L$29-L$19)/10+L22 -> 7.75 | N23: =(N$29-N$19)/10+N22 -> 123.432 | O23: =(O$29-O$19)/10+O22 -> 117.852 | P23: =(P$29-P$19)/10+P22 -> 110.532 | Q23: =(Q$29-Q$19)/10+Q22 -> 127.46 | S23: =(S$29-S$19)/10+S22 -> 15793.6 | T23: =(T$29-T$19)/10+T22 -> 14895.4 | U23: =(U$29-U$19)/10+U22 -> 13710.6 | V23: =(V$29-V$19)/10+V22 -> 16336
B24: 2025 | D24: =(D$29-D$19)/10+D23 -> 425.545 | E24: =(E$29-E$19)/10+E23 -> 426.86 | F24: =(F$29-F$19)/10+F23 -> 432.81 | G24: =(G$29-G$19)/10+G23 -> 435.01 | I24: =(I$29-I$19)/10+I23 -> 7.82 | J24: =(J$29-J$19)/10+J23 -> 7.935 | K24: =(K$29-K$19)/10+K23 -> 8.105 | L24: =(L$29-L$19)/10+L23 -> 7.8 | N24: =(N$29-N$19)/10+N23 -> 128.835 | O24: =(O$29-O$19)/10+O23 -> 122.025 | P24: =(P$29-P$19)/10+P23 -> 113.815 | Q24: =(Q$29-Q$19)/10+Q23 -> 133.85 | S24: =(S$29-S$19)/10+S23 -> 16384 | T24: =(T$29-T$19)/10+T23 -> 15296 | U24: =(U$29-U$19)/10+U23 -> 13976 | V24: =(V$29-V$19)/10+V23 -> 17046
B25: 2026 | D25: =(D$29-D$19)/10+D24 -> 427.744 | E25: =(E$29-E$19)/10+E24 -> 429.344 | F25: =(F$29-F$19)/10+F24 -> 435.958 | G25: =(G$29-G$19)/10+G24 -> 438.562 | I25: =(I$29-I$19)/10+I24 -> 7.868 | J25: =(J$29-J$19)/10+J24 -> 8 | K25: =(K$29-K$19)/10+K24 -> 8.186 | L25: =(L$29-L$19)/10+L24 -> 7.85 | N25: =(N$29-N$19)/10+N24 -> 134.238 | O25: =(O$29-O$19)/10+O24 -> 126.198 | P25: =(P$29-P$19)/10+P24 -> 117.098 | Q25: =(Q$29-Q$19)/10+Q24 -> 140.24 | S25: =(S$29-S$19)/10+S24 -> 16974.4 | T25: =(T$29-T$19)/10+T24 -> 15696.6 | U25: =(U$29-U$19)/10+U24 -> 14241.4 | V25: =(V$29-V$19)/10+V24 -> 17756
B26: 2027 | D26: =(D$29-D$19)/10+D25 -> 429.943 | E26: =(E$29-E$19)/10+E25 -> 431.828 | F26: =(F$29-F$19)/10+F25 -> 439.106 | G26: =(G$29-G$19)/10+G25 -> 442.114 | I26: =(I$29-I$19)/10+I25 -> 7.916 | J26: =(J$29-J$19)/10+J25 -> 8.065 | K26: =(K$29-K$19)/10+K25 -> 8.267 | L26: =(L$29-L$19)/10+L25 -> 7.9 | N26: =(N$29-N$19)/10+N25 -> 139.641 | O26: =(O$29-O$19)/10+O25 -> 130.371 | P26: =(P$29-P$19)/10+P25 -> 120.381 | Q26: =(Q$29-Q$19)/10+Q25 -> 146.63 | S26: =(S$29-S$19)/10+S25 -> 17564.8 | T26: =(T$29-T$19)/10+T25 -> 16097.2 | U26: =(U$29-U$19)/10+U25 -> 14506.8 | V26: =(V$29-V$19)/10+V25 -> 18466
B27: 2028 | D27: =(D$29-D$19)/10+D26 -> 432.142 | E27: =(E$29-E$19)/10+E26 -> 434.312 | F27: =(F$29-F$19)/10+F26 -> 442.254 | G27: =(G$29-G$19)/10+G26 -> 445.666 | I27: =(I$29-I$19)/10+I26 -> 7.964 | J27: =(J$29-J$19)/10+J26 -> 8.13 | K27: =(K$29-K$19)/10+K26 -> 8.348 | L27: =(L$29-L$19)/10+L26 -> 7.95 | N27: =(N$29-N$19)/10+N26 -> 145.044 | O27: =(O$29-O$19)/10+O26 -> 134.544 | P27: =(P$29-P$19)/10+P26 -> 123.664 | Q27: =(Q$29-Q$19)/10+Q26 -> 153.02 | S27: =(S$29-S$19)/10+S26 -> 18155.2 | T27: =(T$29-T$19)/10+T26 -> 16497.8 | U27: =(U$29-U$19)/10+U26 -> 14772.2 | V27: =(V$29-V$19)/10+V26 -> 19176
B28: 2029 | D28: =(D$29-D$19)/10+D27 -> 434.341 | E28: =(E$29-E$19)/10+E27 -> 436.796 | F28: =(F$29-F$19)/10+F27 -> 445.402 | G28: =(G$29-G$19)/10+G27 -> 449.218 | I28: =(I$29-I$19)/10+I27 -> 8.012 | J28: =(J$29-J$19)/10+J27 -> 8.195 | K28: =(K$29-K$19)/10+K27 -> 8.429 | L28: =(L$29-L$19)/10+L27 -> 8 | N28: =(N$29-N$19)/10+N27 -> 150.447 | O28: =(O$29-O$19)/10+O27 -> 138.717 | P28: =(P$29-P$19)/10+P27 -> 126.947 | Q28: =(Q$29-Q$19)/10+Q27 -> 159.41 | S28: =(S$29-S$19)/10+S27 -> 18745.6 | T28: =(T$29-T$19)/10+T27 -> 16898.4 | U28: =(U$29-U$19)/10+U27 -> 15037.6 | V28: =(V$29-V$19)/10+V27 -> 19886
B29: 2030 | D29: 436.54 | E29: 439.28 | F29: 448.55 | G29: 452.77 | I29: 8.06 | J29: 8.26 | K29: 8.51 | L29: 8.05 | N29: 155.85 | O29: 142.89 | P29: 130.23 | Q29: 165.8 | S29: 19336 | T29: 17299 | U29: 15303 | V29: 20596
B30: 2040 | D30: 452.29 | E30: 463.05 | F30: 480.63 | G30: 499.68 | I30: 8.39 | J30: 8.79 | K30: 9.26 | L30: 8.4 | N30: 223.2 | O30: 185.39 | P30: 153.37 | Q30: 260.2 | S30: 26603 | T30: 21091 | U30: 16562 | V30: 30976
B31: 2050 | D31: 460.69 | E31: 483.24 | F31: 511.43 | G31: 559.69 | I31: 8.53 | J31: 9.17 | K31: 9.96 | L31: 8.58 | N31: 291.3 | O31: 230.19 | P31: 171.5 | Q31: 364.7 | S31: 34150 | T31: 25102 | U31: 17218 | V31: 42505
B32: 2060 | D32: 462.9 | E32: 497.49 | F32: 542.95 | G32: 635.79 | I32: 8.49 | J32: 9.38 | K32: 10.57 | L32: 8.59 | N32: 356.29 | O32: 278.62 | P32: 187.41 | Q32: 478.3 | S32: 41965 | T32: 29703 | U32: 17730 | V32: 55681
B33: 2070 | D33: 460.64 | E33: 504.28 | F33: 573.5 | G33: 730.03 | I33: 8.3 | J33: 9.46 | K33: 11.12 | L33: 8.46 | N33: 419.29 | O33: 334.19 | P33: 204.08 | Q33: 605.8 | S33: 50516 | T33: 35326 | U33: 18352 | V33: 71607
B34: 2080 | D34: 453.86 | E34: 504.78 | F34: 599.94 | G34: 841.52 | I34: 7.97 | J34: 9.41 | K34: 11.63 | L34: 8.2 | N34: 475.42 | O34: 394.48 | P34: 221.35 | Q34: 740.6 | S34: 59651 | T34: 41921 | U34: 19032 | V34: 90317
B35: 2090 | D35: 443.09 | E35: 500.71 | F35: 623.13 | G35: 963.84 | I35: 7.51 | J35: 9.25 | K35: 12.13 | L35: 7.83 | N35: 524.88 | O35: 459.9 | P35: 240.09 | Q35: 882.3 | S35: 69890 | T35: 49718 | U35: 19793 | V35: 112681
B36: 2100 | D36: 432.17 | E36: 494.15 | F36: 645.06 | G36: 1088.97 | I36: 6.96 | J36: 9.03 | K36: 12.62 | L36: 7.38 | N36: 565.39 | O36: 531.93 | P36: 261.54 | Q36: 1031 | S36: 81234 | T36: 58906 | U36: 20724 | V36: 139701
B37: 2110 | D37: 421.25 | E37: 487.59 | F37: 666.99 | G37: 1214.1
B38: 2120 | D38: 410.33 | E38: 481.03 | F38: 688.92 | G38: 1339.23
B39: 2130 | D39: 400 | E39: 474.47 | F39: 710.85 | G39: 1464.36
B40: 2140 | D40: 400 | E40: 467.91 | F40: 732.78 | G40: 1589.49
B41: 2150 | D41: 400 | E41: 461.35 | F41: 754.71 | G41: 1714.62
B43: Note: The IPCC's SSP dataset shows projections through 2100. The amounts for 2110 through 2150 were developed by the Society of Actuaries Research Institute solely for the 2023 Student Research Case Study Challenge.
B45: For your information, the explanations below have been copied from the website https://ourworldindata.org/explorers/ipcc-scenarios
B46: What are the Shared Socioeconomic Pathways (SSPs)?
B47: The Shared Socioeconomic Pathways are a set of scenarios which are central to the work of the UN climate reports produced by the Intergovernmental Panel on Climate Change (IPCC).
B49: Why are these scenarios so important for the IPCC report?
...

Sheet Model
E2: Copyright © 2023 by the Society of Actuaries Research Institute. All rights reserved.
B6: Frequency Projection Model of Minor, Medium, and Major Hazard Events Per Year, as a Function of SSP Scenario | AA6: Illustrative Example
B7: One can view the values below either as the expected number of events per year, or as 1 divided by the "return period". An expectation of 0.25 implies a return period of 4 years (on average, an event occurs every 4 years). | AA7: The purpose of this example is a simplified demonstration
B8: An expected value that exceeds 1.00 indicates a return period of less than one year. For example, an expectation of 3 events per year equates to a return period of 4 months. | AA8: of how the projected number of future hazard events might
AA9: be developed from historical hazard event data. This example
B10: INPUT | AA10: is NOT PRESCRIPTIVE and is purposely very simple. Each team
B11: Enter the Expected Number | AA11: may consider or use other approaches, methods, and/or
B12: Hazard Events in 2020 | AA12: assumptions.
B13: Minor | D13: 6 | T13: The risk amplification factor (RAF) ties the change in risk
B14: Medium | D14: 1.6 | T14: to the change in atmospheric CO2. The RAF is equal to | AA14: Using the Historical Hazard Data, a user can define
B15: Major | D15: 0.6 | T15: the square of A / B, where "A" is the projected future level | AA15: breakpoints for Minor/Medium/Major hazard events.
T16: of CO2 and "B" is the level of CO2 in 2020.
AA17: The following illustrative example projects an expected
D18: SSP1‒ 2.6 | H18: SSP2‒3.4 | L18: SSP3‒6.0 | P18: SSP5‒Baseline | AA18: number of hazard events in 2020 for Region 1 using:
D19: Low Emissions | H19: Medium Emissions | L19: High Emissions | P19: Very High Emissions | T19: Risk Amplification Factor (RAF) | AA19: • Per-event property damage cost breakpoints of
B20: Year | D20: Minor | E20: Medium | F20: Major | H20: Minor | I20: Medium | J20: Major | L20: Minor | M20: Medium | N20: Major | P20: Minor | Q20: Medium | R20: Major | T20: =D18 -> SSP1‒ 2.6 | U20: =H18 -> SSP2‒3.4 | V20: =L18 -> SSP3‒6.0 | W20: =P18 -> SSP5‒Baseline | AA20: 500,000 and 5,000,000
B21: 2020 | D21: =ROUND($D$13,3) -> 6 | E21: =ROUND($D$14,3) -> 1.6 | F21: =ROUND($D$15,3) -> 0.6 | H21: =ROUND($D$13,3) -> 6 | I21: =ROUND($D$14,3) -> 1.6 | J21: =ROUND($D$15,3) -> 0.6 | L21: =ROUND($D$13,3) -> 6 | M21: =ROUND($D$14,3) -> 1.6 | N21: =ROUND($D$15,3) -> 0.6 | P21: =ROUND($D$13,3) -> 6 | Q21: =ROUND($D$14,3) -> 1.6 | R21: =ROUND($D$15,3) -> 0.6 | T21: =ROUND(('SSP Scenarios'!D19/'SSP Scenarios'!D$19)^2,5) -> 1 | U21: =ROUND(('SSP Scenarios'!E19/'SSP Scenarios'!E$19)^2,5) -> 1 | V21: =ROUND(('SSP Scenarios'!F19/'SSP Scenarios'!F$19)^2,5) -> 1 | W21: =ROUND(('SSP Scenarios'!G19/'SSP Scenarios'!G$19)^2,5) -> 1 | AA21: • Simple average between 1990 and 2020
B22: 2021 | D22: =ROUND(D$21*$T22,3) -> 6.064 | E22: =ROUND(E$21*$T22,3) -> 1.617 | F22: =ROUND(F$21*$T22,3) -> 0.606 | H22: =ROUND(H$21*$U22,3) -> 6.072 | I22: =ROUND(I$21*$U22,3) -> 1.619 | J22: =ROUND(J$21*$U22,3) -> 0.607 | L22: =ROUND(L$21*$V22,3) -> 6.091 | M22: =ROUND(M$21*$V22,3) -> 1.624 | N22: =ROUND(N$21*$V22,3) -> 0.609 | P22: =ROUND(P$21*$W22,3) -> 6.103 | Q22: =ROUND(Q$21*$W22,3) -> 1.627 | R22: =ROUND(R$21*$W22,3) -> 0.61 | T22: =ROUND(('SSP Scenarios'!D20/'SSP Scenarios'!D$19)^2,5) -> 1.01064 | U22: =ROUND(('SSP Scenarios'!E20/'SSP Scenarios'!E$19)^2,5) -> 1.01202 | V22: =ROUND(('SSP Scenarios'!F20/'SSP Scenarios'!F$19)^2,5) -> 1.01515 | W22: =ROUND(('SSP Scenarios'!G20/'SSP Scenarios'!G$19)^2,5) -> 1.0171
B23: 2022 | D23: =ROUND(D$21*$T23,3) -> 6.128 | E23: =ROUND(E$21*$T23,3) -> 1.634 | F23: =ROUND(F$21*$T23,3) -> 0.613 | H23: =ROUND(H$21*$U23,3) -> 6.145 | I23: =ROUND(I$21*$U23,3) -> 1.639 | J23: =ROUND(J$21*$U23,3) -> 0.614 | L23: =ROUND(L$21*$V23,3) -> 6.183 | M23: =ROUND(M$21*$V23,3) -> 1.649 | N23: =ROUND(N$21*$V23,3) -> 0.618 | P23: =ROUND(P$21*$W23,3) -> 6.206 | Q23: =ROUND(Q$21*$W23,3) -> 1.655 | R23: =ROUND(R$21*$W23,3) -> 0.621 | T23: =ROUND(('SSP Scenarios'!D21/'SSP Scenarios'!D$19)^2,5) -> 1.02133 | U23: =ROUND(('SSP Scenarios'!E21/'SSP Scenarios'!E$19)^2,5) -> 1.02412 | V23: =ROUND(('SSP Scenarios'!F21/'SSP Scenarios'!F$19)^2,5) -> 1.03042 | W23: =ROUND(('SSP Scenarios'!G21/'SSP Scenarios'!G$19)^2,5) -> 1.03434
B24: 2023 | D24: =ROUND(D$21*$T24,3) -> 6.192 | E24: =ROUND(E$21*$T24,3) -> 1.651 | F24: =ROUND(F$21*$T24,3) -> 0.619 | H24: =ROUND(H$21*$U24,3) -> 6.218 | I24: =ROUND(I$21*$U24,3) -> 1.658 | J24: =ROUND(J$21*$U24,3) -> 0.622 | L24: =ROUND(L$21*$V24,3) -> 6.275 | M24: =ROUND(M$21*$V24,3) -> 1.673 | N24: =ROUND(N$21*$V24,3) -> 0.627 | P24: =ROUND(P$21*$W24,3) -> 6.31 | Q24: =ROUND(Q$21*$W24,3) -> 1.683 | R24: =ROUND(R$21*$W24,3) -> 0.631 | T24: =ROUND(('SSP Scenarios'!D22/'SSP Scenarios'!D$19)^2,5) -> 1.03208 | U24: =ROUND(('SSP Scenarios'!E22/'SSP Scenarios'!E$19)^2,5) -> 1.03629 | V24: =ROUND(('SSP Scenarios'!F22/'SSP Scenarios'!F$19)^2,5) -> 1.0458 | W24: =ROUND(('SSP Scenarios'!G22/'SSP Scenarios'!G$19)^2,5) -> 1.05173
B25: 2024 | D25: =ROUND(D$21*$T25,3) -> 6.257 | E25: =ROUND(E$21*$T25,3) -> 1.669 | F25: =ROUND(F$21*$T25,3) -> 0.626 | H25: =ROUND(H$21*$U25,3) -> 6.291 | I25: =ROUND(I$21*$U25,3) -> 1.678 | J25: =ROUND(J$21*$U25,3) -> 0.629 | L25: =ROUND(L$21*$V25,3) -> 6.368 | M25: =ROUND(M$21*$V25,3) -> 1.698 | N25: =ROUND(N$21*$V25,3) -> 0.637 | P25: =ROUND(P$21*$W25,3) -> 6.416 | Q25: =ROUND(Q$21*$W25,3) -> 1.711 | R25: =ROUND(R$21*$W25,3) -> 0.642 | T25: =ROUND(('SSP Scenarios'!D23/'SSP Scenarios'!D$19)^2,5) -> 1.04289 | U25: =ROUND(('SSP Scenarios'!E23/'SSP Scenarios'!E$19)^2,5) -> 1.04852 | V25: =ROUND(('SSP Scenarios'!F23/'SSP Scenarios'!F$19)^2,5) -> 1.06129 | W25: =ROUND(('SSP Scenarios'!G23/'SSP Scenarios'!G$19)^2,5) -> 1.06926
B26: 2025 | D26: =ROUND(D$21*$T26,3) -> 6.323 | E26: =ROUND(E$21*$T26,3) -> 1.686 | F26: =ROUND(F$21*$T26,3) -> 0.632 | H26: =ROUND(H$21*$U26,3) -> 6.365 | I26: =ROUND(I$21*$U26,3) -> 1.697 | J26: =ROUND(J$21*$U26,3) -> 0.636 | L26: =ROUND(L$21*$V26,3) -> 6.461 | M26: =ROUND(M$21*$V26,3) -> 1.723 | N26: =ROUND(N$21*$V26,3) -> 0.646 | P26: =ROUND(P$21*$W26,3) -> 6.522 | Q26: =ROUND(Q$21*$W26,3) -> 1.739 | R26: =ROUND(R$21*$W26,3) -> 0.652 | T26: =ROUND(('SSP Scenarios'!D24/'SSP Scenarios'!D$19)^2,5) -> 1.05375 | U26: =ROUND(('SSP Scenarios'!E24/'SSP Scenarios'!E$19)^2,5) -> 1.06083 | V26: =ROUND(('SSP Scenarios'!F24/'SSP Scenarios'!F$19)^2,5) -> 1.0769 | W26: =ROUND(('SSP Scenarios'!G24/'SSP Scenarios'!G$19)^2,5) -> 1.08694
B27: 2026 | D27: =ROUND(D$21*$T27,3) -> 6.388 | E27: =ROUND(E$21*$T27,3) -> 1.703 | F27: =ROUND(F$21*$T27,3) -> 0.639 | H27: =ROUND(H$21*$U27,3) -> 6.439 | I27: =ROUND(I$21*$U27,3) -> 1.717 | J27: =ROUND(J$21*$U27,3) -> 0.644 | L27: =ROUND(L$21*$V27,3) -> 6.556 | M27: =ROUND(M$21*$V27,3) -> 1.748 | N27: =ROUND(N$21*$V27,3) -> 0.656 | P27: =ROUND(P$21*$W27,3) -> 6.629 | Q27: =ROUND(Q$21*$W27,3) -> 1.768 | R27: =ROUND(R$21*$W27,3) -> 0.663 | T27: =ROUND(('SSP Scenarios'!D25/'SSP Scenarios'!D$19)^2,5) -> 1.06467 | U27: =ROUND(('SSP Scenarios'!E25/'SSP Scenarios'!E$19)^2,5) -> 1.07322 | V27: =ROUND(('SSP Scenarios'!F25/'SSP Scenarios'!F$19)^2,5) -> 1.09263 | W27: =ROUND(('SSP Scenarios'!G25/'SSP Scenarios'!G$19)^2,5) -> 1.10476
B28: 2027 | D28: =ROUND(D$21*$T28,3) -> 6.454 | E28: =ROUND(E$21*$T28,3) -> 1.721 | F28: =ROUND(F$21*$T28,3) -> 0.645 | H28: =ROUND(H$21*$U28,3) -> 6.514 | I28: =ROUND(I$21*$U28,3) -> 1.737 | J28: =ROUND(J$21*$U28,3) -> 0.651 | L28: =ROUND(L$21*$V28,3) -> 6.651 | M28: =ROUND(M$21*$V28,3) -> 1.774 | N28: =ROUND(N$21*$V28,3) -> 0.665 | P28: =ROUND(P$21*$W28,3) -> 6.736 | Q28: =ROUND(Q$21*$W28,3) -> 1.796 | R28: =ROUND(R$21*$W28,3) -> 0.674 | T28: =ROUND(('SSP Scenarios'!D26/'SSP Scenarios'!D$19)^2,5) -> 1.07564 | U28: =ROUND(('SSP Scenarios'!E26/'SSP Scenarios'!E$19)^2,5) -> 1.08567 | V28: =ROUND(('SSP Scenarios'!F26/'SSP Scenarios'!F$19)^2,5) -> 1.10846 | W28: =ROUND(('SSP Scenarios'!G26/'SSP Scenarios'!G$19)^2,5) -> 1.12273
B29: 2028 | D29: =ROUND(D$21*$T29,3) -> 6.52 | E29: =ROUND(E$21*$T29,3) -> 1.739 | F29: =ROUND(F$21*$T29,3) -> 0.652 | H29: =ROUND(H$21*$U29,3) -> 6.589 | I29: =ROUND(I$21*$U29,3) -> 1.757 | J29: =ROUND(J$21*$U29,3) -> 0.659 | L29: =ROUND(L$21*$V29,3) -> 6.746 | M29: =ROUND(M$21*$V29,3) -> 1.799 | N29: =ROUND(N$21*$V29,3) -> 0.675 | P29: =ROUND(P$21*$W29,3) -> 6.845 | Q29: =ROUND(Q$21*$W29,3) -> 1.825 | R29: =ROUND(R$21*$W29,3) -> 0.685 | T29: =ROUND(('SSP Scenarios'!D27/'SSP Scenarios'!D$19)^2,5) -> 1.08667 | U29: =ROUND(('SSP Scenarios'!E27/'SSP Scenarios'!E$19)^2,5) -> 1.0982 | V29: =ROUND(('SSP Scenarios'!F27/'SSP Scenarios'!F$19)^2,5) -> 1.12441 | W29: =ROUND(('SSP Scenarios'!G27/'SSP Scenarios'!G$19)^2,5) -> 1.14084
B30: 2029 | D30: =ROUND(D$21*$T30,3) -> 6.587 | E30: =ROUND(E$21*$T30,3) -> 1.756 | F30: =ROUND(F$21*$T30,3) -> 0.659 | H30: =ROUND(H$21*$U30,3) -> 6.665 | I30: =ROUND(I$21*$U30,3) -> 1.777 | J30: =ROUND(J$21*$U30,3) -> 0.666 | L30: =ROUND(L$21*$V30,3) -> 6.843 | M30: =ROUND(M$21*$V30,3) -> 1.825 | N30: =ROUND(N$21*$V30,3) -> 0.684 | P30: =ROUND(P$21*$W30,3) -> 6.955 | Q30: =ROUND(Q$21*$W30,3) -> 1.855 | R30: =ROUND(R$21*$W30,3) -> 0.695 | T30: =ROUND(('SSP Scenarios'!D28/'SSP Scenarios'!D$19)^2,5) -> 1.09776 | U30: =ROUND(('SSP Scenarios'!E28/'SSP Scenarios'!E$19)^2,5) -> 1.1108 | V30: =ROUND(('SSP Scenarios'!F28/'SSP Scenarios'!F$19)^2,5) -> 1.14048 | W30: =ROUND(('SSP Scenarios'!G28/'SSP Scenarios'!G$19)^2,5) -> 1.1591
B31: 2030 | D31: =ROUND(D$21*$T31,3) -> 6.653 | E31: =ROUND(E$21*$T31,3) -> 1.774 | F31: =ROUND(F$21*$T31,3) -> 0.665 | H31: =ROUND(H$21*$U31,3) -> 6.741 | I31: =ROUND(I$21*$U31,3) -> 1.798 | J31: =ROUND(J$21*$U31,3) -> 0.674 | L31: =ROUND(L$21*$V31,3) -> 6.94 | M31: =ROUND(M$21*$V31,3) -> 1.851 | N31: =ROUND(N$21*$V31,3) -> 0.694 | P31: =ROUND(P$21*$W31,3) -> 7.065 | Q31: =ROUND(Q$21*$W31,3) -> 1.884 | R31: =ROUND(R$21*$W31,3) -> 0.707 | T31: =ROUND(('SSP Scenarios'!D29/'SSP Scenarios'!D$19)^2,5) -> 1.1089 | U31: =ROUND(('SSP Scenarios'!E29/'SSP Scenarios'!E$19)^2,5) -> 1.12346 | V31: =ROUND(('SSP Scenarios'!F29/'SSP Scenarios'!F$19)^2,5) -> 1.15665 | W31: =ROUND(('SSP Scenarios'!G29/'SSP Scenarios'!G$19)^2,5) -> 1.1775 | AA31: • Ignores duration, fatalities, injuries and type of hazard event
B32: 2040 | D32: =ROUND(D$21*$T32,3) -> 7.142 | E32: =ROUND(E$21*$T32,3) -> 1.905 | F32: =ROUND(F$21*$T32,3) -> 0.714 | H32: =ROUND(H$21*$U32,3) -> 7.49 | I32: =ROUND(I$21*$U32,3) -> 1.997 | J32: =ROUND(J$21*$U32,3) -> 0.749 | L32: =ROUND(L$21*$V32,3) -> 7.968 | M32: =ROUND(M$21*$V32,3) -> 2.125 | N32: =ROUND(N$21*$V32,3) -> 0.797 | P32: =ROUND(P$21*$W32,3) -> 8.605 | Q32: =ROUND(Q$21*$W32,3) -> 2.295 | R32: =ROUND(R$21*$W32,3) -> 0.86 | T32: =ROUND(('SSP Scenarios'!D30/'SSP Scenarios'!D$19)^2,5) -> 1.19036 | U32: =ROUND(('SSP Scenarios'!E30/'SSP Scenarios'!E$19)^2,5) -> 1.24834 | V32: =ROUND(('SSP Scenarios'!F30/'SSP Scenarios'!F$19)^2,5) -> 1.32802 | W32: =ROUND(('SSP Scenarios'!G30/'SSP Scenarios'!G$19)^2,5) -> 1.43414
B33: 2050 | D33: =ROUND(D$21*$T33,3) -> 7.41 | E33: =ROUND(E$21*$T33,3) -> 1.976 | F33: =ROUND(F$21*$T33,3) -> 0.741 | H33: =ROUND(H$21*$U33,3) -> 8.157 | I33: =ROUND(I$21*$U33,3) -> 2.175 | J33: =ROUND(J$21*$U33,3) -> 0.816 | L33: =ROUND(L$21*$V33,3) -> 9.022 | M33: =ROUND(M$21*$V33,3) -> 2.406 | N33: =ROUND(N$21*$V33,3) -> 0.902 | P33: =ROUND(P$21*$W33,3) -> 10.796 | Q33: =ROUND(Q$21*$W33,3) -> 2.879 | R33: =ROUND(R$21*$W33,3) -> 1.08 | T33: =ROUND(('SSP Scenarios'!D31/'SSP Scenarios'!D$19)^2,5) -> 1.23499 | U33: =ROUND(('SSP Scenarios'!E31/'SSP Scenarios'!E$19)^2,5) -> 1.35957 | V33: =ROUND(('SSP Scenarios'!F31/'SSP Scenarios'!F$19)^2,5) -> 1.50368 | W33: =ROUND(('SSP Scenarios'!G31/'SSP Scenarios'!G$19)^2,5) -> 1.7993 | AA33: The result is a simple approximation that may be entered as
B34: 2060 | D34: =ROUND(D$21*$T34,3) -> 7.481 | E34: =ROUND(E$21*$T34,3) -> 1.995 | F34: =ROUND(F$21*$T34,3) -> 0.748 | H34: =ROUND(H$21*$U34,3) -> 8.646 | I34: =ROUND(I$21*$U34,3) -> 2.306 | J34: =ROUND(J$21*$U34,3) -> 0.865 | L34: =ROUND(L$21*$V34,3) -> 10.168 | M34: =ROUND(M$21*$V34,3) -> 2.712 | N34: =ROUND(N$21*$V34,3) -> 1.017 | P34: =ROUND(P$21*$W34,3) -> 13.931 | Q34: =ROUND(Q$21*$W34,3) -> 3.715 | R34: =ROUND(R$21*$W34,3) -> 1.393 | T34: =ROUND(('SSP Scenarios'!D32/'SSP Scenarios'!D$19)^2,5) -> 1.24687 | U34: =ROUND(('SSP Scenarios'!E32/'SSP Scenarios'!E$19)^2,5) -> 1.44094 | V34: =ROUND(('SSP Scenarios'!F32/'SSP Scenarios'!F$19)^2,5) -> 1.69473 | W34: =ROUND(('SSP Scenarios'!G32/'SSP Scenarios'!G$19)^2,5) -> 2.32185 | AA34: starting inputs in model to the left.
B35: 2070 | D35: =ROUND(D$21*$T35,3) -> 7.408 | E35: =ROUND(E$21*$T35,3) -> 1.976 | F35: =ROUND(F$21*$T35,3) -> 0.741 | H35: =ROUND(H$21*$U35,3) -> 8.883 | I35: =ROUND(I$21*$U35,3) -> 2.369 | J35: =ROUND(J$21*$U35,3) -> 0.888 | L35: =ROUND(L$21*$V35,3) -> 11.345 | M35: =ROUND(M$21*$V35,3) -> 3.025 | N35: =ROUND(N$21*$V35,3) -> 1.134 | P35: =ROUND(P$21*$W35,3) -> 18.367 | Q35: =ROUND(Q$21*$W35,3) -> 4.898 | R35: =ROUND(R$21*$W35,3) -> 1.837 | T35: =ROUND(('SSP Scenarios'!D33/'SSP Scenarios'!D$19)^2,5) -> 1.23472 | U35: =ROUND(('SSP Scenarios'!E33/'SSP Scenarios'!E$19)^2,5) -> 1.48054 | V35: =ROUND(('SSP Scenarios'!F33/'SSP Scenarios'!F$19)^2,5) -> 1.89081 | W35: =ROUND(('SSP Scenarios'!G33/'SSP Scenarios'!G$19)^2,5) -> 3.06118
B36: 2080 | D36: =ROUND(D$21*$T36,3) -> 7.192 | E36: =ROUND(E$21*$T36,3) -> 1.918 | F36: =ROUND(F$21*$T36,3) -> 0.719 | H36: =ROUND(H$21*$U36,3) -> 8.901 | I36: =ROUND(I$21*$U36,3) -> 2.374 | J36: =ROUND(J$21*$U36,3) -> 0.89 | L36: =ROUND(L$21*$V36,3) -> 12.415 | M36: =ROUND(M$21*$V36,3) -> 3.311 | N36: =ROUND(N$21*$V36,3) -> 1.242 | P36: =ROUND(P$21*$W36,3) -> 24.405 | Q36: =ROUND(Q$21*$W36,3) -> 6.508 | R36: =ROUND(R$21*$W36,3) -> 2.441 | T36: =ROUND(('SSP Scenarios'!D34/'SSP Scenarios'!D$19)^2,5) -> 1.19864 | U36: =ROUND(('SSP Scenarios'!E34/'SSP Scenarios'!E$19)^2,5) -> 1.48348 | V36: =ROUND(('SSP Scenarios'!F34/'SSP Scenarios'!F$19)^2,5) -> 2.06918 | W36: =ROUND(('SSP Scenarios'!G34/'SSP Scenarios'!G$19)^2,5) -> 4.06758 | AB36: Minor | AC36: Medium | AD36: Major
B37: 2090 | D37: =ROUND(D$21*$T37,3) -> 6.855 | E37: =ROUND(E$21*$T37,3) -> 1.828 | F37: =ROUND(F$21*$T37,3) -> 0.685 | H37: =ROUND(H$21*$U37,3) -> 8.758 | I37: =ROUND(I$21*$U37,3) -> 2.335 | J37: =ROUND(J$21*$U37,3) -> 0.876 | L37: =ROUND(L$21*$V37,3) -> 13.393 | M37: =ROUND(M$21*$V37,3) -> 3.572 | N37: =ROUND(N$21*$V37,3) -> 1.339 | P37: =ROUND(P$21*$W37,3) -> 32.016 | Q37: =ROUND(Q$21*$W37,3) -> 8.538 | R37: =ROUND(R$21*$W37,3) -> 3.202 | T37: =ROUND(('SSP Scenarios'!D35/'SSP Scenarios'!D$19)^2,5) -> 1.14243 | U37: =ROUND(('SSP Scenarios'!E35/'SSP Scenarios'!E$19)^2,5) -> 1.45965 | V37: =ROUND(('SSP Scenarios'!F35/'SSP Scenarios'!F$19)^2,5) -> 2.23223 | W37: =ROUND(('SSP Scenarios'!G35/'SSP Scenarios'!G$19)^2,5) -> 5.33602 | AA37: Average | AB37: =AVERAGE(AB42:AB72) -> 5.9677419 | AC37: =AVERAGE(AC42:AC72) -> 1.6451613 | AD37: =AVERAGE(AD42:AD72) -> 0.61290323
B38: 2100 | D38: =ROUND(D$21*$T38,3) -> 6.521 | E38: =ROUND(E$21*$T38,3) -> 1.739 | F38: =ROUND(F$21*$T38,3) -> 0.652 | H38: =ROUND(H$21*$U38,3) -> 8.53 | I38: =ROUND(I$21*$U38,3) -> 2.275 | J38: =ROUND(J$21*$U38,3) -> 0.853 | L38: =ROUND(L$21*$V38,3) -> 14.353 | M38: =ROUND(M$21*$V38,3) -> 3.827 | N38: =ROUND(N$21*$V38,3) -> 1.435 | P38: =ROUND(P$21*$W38,3) -> 40.869 | Q38: =ROUND(Q$21*$W38,3) -> 10.898 | R38: =ROUND(R$21*$W38,3) -> 4.087 | T38: =ROUND(('SSP Scenarios'!D36/'SSP Scenarios'!D$19)^2,5) -> 1.08681 | U38: =ROUND(('SSP Scenarios'!E36/'SSP Scenarios'!E$19)^2,5) -> 1.42166 | V38: =ROUND(('SSP Scenarios'!F36/'SSP Scenarios'!F$19)^2,5) -> 2.39212 | W38: =ROUND(('SSP Scenarios'!G36/'SSP Scenarios'!G$19)^2,5) -> 6.81144 | AA38: Rounded | AB38: =ROUND(AB37,1) -> 6 | AC38: =ROUND(AC37,1) -> 1.6 | AD38: =ROUND(AD37,1) -> 0.6
B39: 2110 | D39: =ROUND(D$21*$T39,3) -> 6.196 | E39: =ROUND(E$21*$T39,3) -> 1.652 | F39: =ROUND(F$21*$T39,3) -> 0.62 | H39: =ROUND(H$21*$U39,3) -> 8.305 | I39: =ROUND(I$21*$U39,3) -> 2.215 | J39: =ROUND(J$21*$U39,3) -> 0.83 | L39: =ROUND(L$21*$V39,3) -> 15.345 | M39: =ROUND(M$21*$V39,3) -> 4.092 | N39: =ROUND(N$21*$V39,3) -> 1.535 | P39: =ROUND(P$21*$W39,3) -> 50.8 | Q39: =ROUND(Q$21*$W39,3) -> 13.547 | R39: =ROUND(R$21*$W39,3) -> 5.08 | T39: =ROUND(('SSP Scenarios'!D37/'SSP Scenarios'!D$19)^2,5) -> 1.03259 | U39: =ROUND(('SSP Scenarios'!E37/'SSP Scenarios'!E$19)^2,5) -> 1.38416 | V39: =ROUND(('SSP Scenarios'!F37/'SSP Scenarios'!F$19)^2,5) -> 2.55753 | W39: =ROUND(('SSP Scenarios'!G37/'SSP Scenarios'!G$19)^2,5) -> 8.46674
B40: 2120 | D40: =ROUND(D$21*$T40,3) -> 5.878 | E40: =ROUND(E$21*$T40,3) -> 1.568 | F40: =ROUND(F$21*$T40,3) -> 0.588 | H40: =ROUND(H$21*$U40,3) -> 8.083 | I40: =ROUND(I$21*$U40,3) -> 2.155 | J40: =ROUND(J$21*$U40,3) -> 0.808 | L40: =ROUND(L$21*$V40,3) -> 16.371 | M40: =ROUND(M$21*$V40,3) -> 4.366 | N40: =ROUND(N$21*$V40,3) -> 1.637 | P40: =ROUND(P$21*$W40,3) -> 61.811 | Q40: =ROUND(Q$21*$W40,3) -> 16.483 | R40: =ROUND(R$21*$W40,3) -> 6.181 | T40: =ROUND(('SSP Scenarios'!D38/'SSP Scenarios'!D$19)^2,5) -> 0.97974 | U40: =ROUND(('SSP Scenarios'!E38/'SSP Scenarios'!E$19)^2,5) -> 1.34717 | V40: =ROUND(('SSP Scenarios'!F38/'SSP Scenarios'!F$19)^2,5) -> 2.72847 | W40: =ROUND(('SSP Scenarios'!G38/'SSP Scenarios'!G$19)^2,5) -> 10.30191 | AA40: Historical Hazard Data
B41: 2130 | D41: =ROUND(D$21*$T41,3) -> 5.586 | E41: =ROUND(E$21*$T41,3) -> 1.49 | F41: =ROUND(F$21*$T41,3) -> 0.559 | H41: =ROUND(H$21*$U41,3) -> 7.864 | I41: =ROUND(I$21*$U41,3) -> 2.097 | J41: =ROUND(J$21*$U41,3) -> 0.786 | L41: =ROUND(L$21*$V41,3) -> 17.43 | M41: =ROUND(M$21*$V41,3) -> 4.648 | N41: =ROUND(N$21*$V41,3) -> 1.743 | P41: =ROUND(P$21*$W41,3) -> 73.902 | Q41: =ROUND(Q$21*$W41,3) -> 19.707 | R41: =ROUND(R$21*$W41,3) -> 7.39 | T41: =ROUND(('SSP Scenarios'!D39/'SSP Scenarios'!D$19)^2,5) -> 0.93104 | U41: =ROUND(('SSP Scenarios'!E39/'SSP Scenarios'!E$19)^2,5) -> 1.31067 | V41: =ROUND(('SSP Scenarios'!F39/'SSP Scenarios'!F$19)^2,5) -> 2.90495 | W41: =ROUND(('SSP Scenarios'!G39/'SSP Scenarios'!G$19)^2,5) -> 12.31695 | AB41: Minor | AC41: Medium | AD41: Major
B42: 2140 | D42: =ROUND(D$21*$T42,3) -> 5.586 | E42: =ROUND(E$21*$T42,3) -> 1.49 | F42: =ROUND(F$21*$T42,3) -> 0.559 | H42: =ROUND(H$21*$U42,3) -> 7.648 | I42: =ROUND(I$21*$U42,3) -> 2.039 | J42: =ROUND(J$21*$U42,3) -> 0.765 | L42: =ROUND(L$21*$V42,3) -> 18.522 | M42: =ROUND(M$21*$V42,3) -> 4.939 | N42: =ROUND(N$21*$V42,3) -> 1.852 | P42: =ROUND(P$21*$W42,3) -> 87.071 | Q42: =ROUND(Q$21*$W42,3) -> 23.219 | R42: =ROUND(R$21*$W42,3) -> 8.707 | T42: =ROUND(('SSP Scenarios'!D40/'SSP Scenarios'!D$19)^2,5) -> 0.93104 | U42: =ROUND(('SSP Scenarios'!E40/'SSP Scenarios'!E$19)^2,5) -> 1.27468 | V42: =ROUND(('SSP Scenarios'!F40/'SSP Scenarios'!F$19)^2,5) -> 3.08695 | W42: =ROUND(('SSP Scenarios'!G40/'SSP Scenarios'!G$19)^2,5) -> 14.51185 | AA42: 1990 | AB42: 9 | AC42: 4 | AD42: 0
B43: 2150 | D43: =ROUND(D$21*$T43,3) -> 5.586 | E43: =ROUND(E$21*$T43,3) -> 1.49 | F43: =ROUND(F$21*$T43,3) -> 0.559 | H43: =ROUND(H$21*$U43,3) -> 7.435 | I43: =ROUND(I$21*$U43,3) -> 1.983 | J43: =ROUND(J$21*$U43,3) -> 0.744 | L43: =ROUND(L$21*$V43,3) -> 19.647 | M43: =ROUND(M$21*$V43,3) -> 5.239 | N43: =ROUND(N$21*$V43,3) -> 1.965 | P43: =ROUND(P$21*$W43,3) -> 101.32 | Q43: =ROUND(Q$21*$W43,3) -> 27.019 | R43: =ROUND(R$21*$W43,3) -> 10.132 | T43: =ROUND(('SSP Scenarios'!D41/'SSP Scenarios'!D$19)^2,5) -> 0.93104 | U43: =ROUND(('SSP Scenarios'!E41/'SSP Scenarios'!E$19)^2,5) -> 1.23919 | V43: =ROUND(('SSP Scenarios'!F41/'SSP Scenarios'!F$19)^2,5) -> 3.27448 | W43: =ROUND(('SSP Scenarios'!G41/'SSP Scenarios'!G$19)^2,5) -> 16.88663 | AA43: 1991 | AB43: 7 | AC43: 3 | AD43: 0
AA44: 1992 | AB44: 7 | AC44: 3 | AD44: 0
...

Sheet Economic Projections
A1: Census Projections using 2020 as base value of 1 | G1: GDP Projections using 2020 as base value of 1 | M1: GDP per capita projections using 2020 as base value of 1
B2: SSP1 | C2: SSP2 | D2: SSP3 | E2: SSP5 | H2: SSP1 | I2: SSP2 | J2: SSP3 | K2: SSP5 | N2: SSP1 | O2: SSP2 | P2: SSP3 | Q2: SSP5
A3: 2020 | B3: 1 | C3: 1 | D3: 1 | E3: 1 | G3: 2020 | H3: 1 | I3: 1 | J3: 1 | K3: 1 | M3: 2020 | N3: 1 | O3: 1 | P3: 1 | Q3: 1
A4: 2021 | B4: ='SSP Scenarios'!I20/'SSP Scenarios'!I$19 -> 1.0063325 | C4: ='SSP Scenarios'!J20/'SSP Scenarios'!J$19 -> 1.0085414 | D4: ='SSP Scenarios'!K20/'SSP Scenarios'!K$19 -> 1.0105195 | E4: ='SSP Scenarios'!L20/'SSP Scenarios'!L$19 -> 1.0066225 | G4: 2021 | H4: ='SSP Scenarios'!N20/'SSP Scenarios'!N$19 -> 1.0530642 | I4: ='SSP Scenarios'!O20/'SSP Scenarios'!O$19 -> 1.0412515 | J4: ='SSP Scenarios'!P20/'SSP Scenarios'!P$19 -> 1.0337064 | K4: ='SSP Scenarios'!Q20/'SSP Scenarios'!Q$19 -> 1.0627085 | M4: 2021 | N4: ='SSP Scenarios'!S20/'SSP Scenarios'!S$19 -> 1.0439547 | O4: ='SSP Scenarios'!T20/'SSP Scenarios'!T$19 -> 1.0301362 | P4: ='SSP Scenarios'!U20/'SSP Scenarios'!U$19 -> 1.0209819 | Q4: ='SSP Scenarios'!V20/'SSP Scenarios'!V$19 -> 1.0526082
A5: 2022 | B5: ='SSP Scenarios'!I21/'SSP Scenarios'!I$19 -> 1.0126649 | C5: ='SSP Scenarios'!J21/'SSP Scenarios'!J$19 -> 1.0170828 | D5: ='SSP Scenarios'!K21/'SSP Scenarios'!K$19 -> 1.021039 | E5: ='SSP Scenarios'!L21/'SSP Scenarios'!L$19 -> 1.013245 | G5: 2022 | H5: ='SSP Scenarios'!N21/'SSP Scenarios'!N$19 -> 1.1061285 | I5: ='SSP Scenarios'!O21/'SSP Scenarios'!O$19 -> 1.082503 | J5: ='SSP Scenarios'!P21/'SSP Scenarios'!P$19 -> 1.0674127 | K5: ='SSP Scenarios'!Q21/'SSP Scenarios'!Q$19 -> 1.1254171 | M5: 2022 | N5: ='SSP Scenarios'!S21/'SSP Scenarios'!S$19 -> 1.0879095 | O5: ='SSP Scenarios'!T21/'SSP Scenarios'!T$19 -> 1.0602723 | P5: ='SSP Scenarios'!U21/'SSP Scenarios'!U$19 -> 1.0419638 | Q5: ='SSP Scenarios'!V21/'SSP Scenarios'!V$19 -> 1.1052164
A6: 2023 | B6: ='SSP Scenarios'!I22/'SSP Scenarios'!I$19 -> 1.0189974 | C6: ='SSP Scenarios'!J22/'SSP Scenarios'!J$19 -> 1.0256242 | D6: ='SSP Scenarios'!K22/'SSP Scenarios'!K$19 -> 1.0315584 | E6: ='SSP Scenarios'!L22/'SSP Scenarios'!L$19 -> 1.0198675 | G6: 2023 | H6: ='SSP Scenarios'!N22/'SSP Scenarios'!N$19 -> 1.1591927 | I6: ='SSP Scenarios'!O22/'SSP Scenarios'!O$19 -> 1.1237544 | J6: ='SSP Scenarios'!P22/'SSP Scenarios'!P$19 -> 1.1011191 | K6: ='SSP Scenarios'!Q22/'SSP Scenarios'!Q$19 -> 1.1881256 | M6: 2023 | N6: ='SSP Scenarios'!S22/'SSP Scenarios'!S$19 -> 1.1318642 | O6: ='SSP Scenarios'!T22/'SSP Scenarios'!T$19 -> 1.0904085 | P6: ='SSP Scenarios'!U22/'SSP Scenarios'!U$19 -> 1.0629457 | Q6: ='SSP Scenarios'!V22/'SSP Scenarios'!V$19 -> 1.1578245
A7: 2024 | B7: ='SSP Scenarios'!I23/'SSP Scenarios'!I$19 -> 1.0253298 | C7: ='SSP Scenarios'!J23/'SSP Scenarios'!J$19 -> 1.0341656 | D7: ='SSP Scenarios'!K23/'SSP Scenarios'!K$19 -> 1.0420779 | E7: ='SSP Scenarios'!L23/'SSP Scenarios'!L$19 -> 1.0264901 | G7: 2024 | H7: ='SSP Scenarios'!N23/'SSP Scenarios'!N$19 -> 1.2122569 | I7: ='SSP Scenarios'!O23/'SSP Scenarios'!O$19 -> 1.1650059 | J7: ='SSP Scenarios'!P23/'SSP Scenarios'!P$19 -> 1.1348255 | K7: ='SSP Scenarios'!Q23/'SSP Scenarios'!Q$19 -> 1.2508342 | M7: 2024 | N7: ='SSP Scenarios'!S23/'SSP Scenarios'!S$19 -> 1.1758189 | O7: ='SSP Scenarios'!T23/'SSP Scenarios'!T$19 -> 1.1205446 | P7: ='SSP Scenarios'!U23/'SSP Scenarios'!U$19 -> 1.0839276 | Q7: ='SSP Scenarios'!V23/'SSP Scenarios'!V$19 -> 1.2104327
A8: 2025 | B8: ='SSP Scenarios'!I24/'SSP Scenarios'!I$19 -> 1.0316623 | C8: ='SSP Scenarios'!J24/'SSP Scenarios'!J$19 -> 1.042707 | D8: ='SSP Scenarios'!K24/'SSP Scenarios'!K$19 -> 1.0525974 | E8: ='SSP Scenarios'!L24/'SSP Scenarios'!L$19 -> 1.0331126 | G8: 2025 | H8: ='SSP Scenarios'!N24/'SSP Scenarios'!N$19 -> 1.2653212 | I8: ='SSP Scenarios'!O24/'SSP Scenarios'!O$19 -> 1.2062574 | J8: ='SSP Scenarios'!P24/'SSP Scenarios'!P$19 -> 1.1685318 | K8: ='SSP Scenarios'!Q24/'SSP Scenarios'!Q$19 -> 1.3135427 | M8: 2025 | N8: ='SSP Scenarios'!S24/'SSP Scenarios'!S$19 -> 1.2197737 | O8: ='SSP Scenarios'!T24/'SSP Scenarios'!T$19 -> 1.1506808 | P8: ='SSP Scenarios'!U24/'SSP Scenarios'!U$19 -> 1.1049095 | Q8: ='SSP Scenarios'!V24/'SSP Scenarios'!V$19 -> 1.2630409
A9: 2026 | B9: ='SSP Scenarios'!I25/'SSP Scenarios'!I$19 -> 1.0379947 | C9: ='SSP Scenarios'!J25/'SSP Scenarios'!J$19 -> 1.0512484 | D9: ='SSP Scenarios'!K25/'SSP Scenarios'!K$19 -> 1.0631169 | E9: ='SSP Scenarios'!L25/'SSP Scenarios'!L$19 -> 1.0397351 | G9: 2026 | H9: ='SSP Scenarios'!N25/'SSP Scenarios'!N$19 -> 1.3183854 | I9: ='SSP Scenarios'!O25/'SSP Scenarios'!O$19 -> 1.2475089 | J9: ='SSP Scenarios'!P25/'SSP Scenarios'!P$19 -> 1.2022382 | K9: ='SSP Scenarios'!Q25/'SSP Scenarios'!Q$19 -> 1.3762512 | M9: 2026 | N9: ='SSP Scenarios'!S25/'SSP Scenarios'!S$19 -> 1.2637284 | O9: ='SSP Scenarios'!T25/'SSP Scenarios'!T$19 -> 1.180817 | P9: ='SSP Scenarios'!U25/'SSP Scenarios'!U$19 -> 1.1258914 | Q9: ='SSP Scenarios'!V25/'SSP Scenarios'!V$19 -> 1.3156491
A10: 2027 | B10: ='SSP Scenarios'!I26/'SSP Scenarios'!I$19 -> 1.0443272 | C10: ='SSP Scenarios'!J26/'SSP Scenarios'!J$19 -> 1.0597898 | D10: ='SSP Scenarios'!K26/'SSP Scenarios'!K$19 -> 1.0736364 | E10: ='SSP Scenarios'!L26/'SSP Scenarios'!L$19 -> 1.0463576 | G10: 2027 | H10: ='SSP Scenarios'!N26/'SSP Scenarios'!N$19 -> 1.3714496 | I10: ='SSP Scenarios'!O26/'SSP Scenarios'!O$19 -> 1.2887604 | J10: ='SSP Scenarios'!P26/'SSP Scenarios'!P$19 -> 1.2359446 | K10: ='SSP Scenarios'!Q26/'SSP Scenarios'!Q$19 -> 1.4389598 | M10: 2027 | N10: ='SSP Scenarios'!S26/'SSP Scenarios'!S$19 -> 1.3076831 | O10: ='SSP Scenarios'!T26/'SSP Scenarios'!T$19 -> 1.2109531 | P10: ='SSP Scenarios'!U26/'SSP Scenarios'!U$19 -> 1.1468733 | Q10: ='SSP Scenarios'!V26/'SSP Scenarios'!V$19 -> 1.3682573
A11: 2028 | B11: ='SSP Scenarios'!I27/'SSP Scenarios'!I$19 -> 1.0506596 | C11: ='SSP Scenarios'!J27/'SSP Scenarios'!J$19 -> 1.0683311 | D11: ='SSP Scenarios'!K27/'SSP Scenarios'!K$19 -> 1.0841558 | E11: ='SSP Scenarios'!L27/'SSP Scenarios'!L$19 -> 1.0529801 | G11: 2028 | H11: ='SSP Scenarios'!N27/'SSP Scenarios'!N$19 -> 1.4245138 | I11: ='SSP Scenarios'!O27/'SSP Scenarios'!O$19 -> 1.3300119 | J11: ='SSP Scenarios'!P27/'SSP Scenarios'!P$19 -> 1.2696509 | K11: ='SSP Scenarios'!Q27/'SSP Scenarios'!Q$19 -> 1.5016683 | M11: 2028 | N11: ='SSP Scenarios'!S27/'SSP Scenarios'!S$19 -> 1.3516379 | O11: ='SSP Scenarios'!T27/'SSP Scenarios'!T$19 -> 1.2410893 | P11: ='SSP Scenarios'!U27/'SSP Scenarios'!U$19 -> 1.1678552 | Q11: ='SSP Scenarios'!V27/'SSP Scenarios'!V$19 -> 1.4208654
A12: 2029 | B12: ='SSP Scenarios'!I28/'SSP Scenarios'!I$19 -> 1.0569921 | C12: ='SSP Scenarios'!J28/'SSP Scenarios'!J$19 -> 1.0768725 | D12: ='SSP Scenarios'!K28/'SSP Scenarios'!K$19 -> 1.0946753 | E12: ='SSP Scenarios'!L28/'SSP Scenarios'!L$19 -> 1.0596026 | G12: 2029 | H12: ='SSP Scenarios'!N28/'SSP Scenarios'!N$19 -> 1.4775781 | I12: ='SSP Scenarios'!O28/'SSP Scenarios'!O$19 -> 1.3712633 | J12: ='SSP Scenarios'!P28/'SSP Scenarios'!P$19 -> 1.3033573 | K12: ='SSP Scenarios'!Q28/'SSP Scenarios'!Q$19 -> 1.5643768 | M12: 2029 | N12: ='SSP Scenarios'!S28/'SSP Scenarios'!S$19 -> 1.3955926 | O12: ='SSP Scenarios'!T28/'SSP Scenarios'!T$19 -> 1.2712255 | P12: ='SSP Scenarios'!U28/'SSP Scenarios'!U$19 -> 1.1888371 | Q12: ='SSP Scenarios'!V28/'SSP Scenarios'!V$19 -> 1.4734736
A13: 2030 | B13: ='SSP Scenarios'!I29/'SSP Scenarios'!I$19 -> 1.0633245 | C13: ='SSP Scenarios'!J29/'SSP Scenarios'!J$19 -> 1.0854139 | D13: ='SSP Scenarios'!K29/'SSP Scenarios'!K$19 -> 1.1051948 | E13: ='SSP Scenarios'!L29/'SSP Scenarios'!L$19 -> 1.0662252 | G13: 2030 | H13: ='SSP Scenarios'!N29/'SSP Scenarios'!N$19 -> 1.5306423 | I13: ='SSP Scenarios'!O29/'SSP Scenarios'!O$19 -> 1.4125148 | J13: ='SSP Scenarios'!P29/'SSP Scenarios'!P$19 -> 1.3370637 | K13: ='SSP Scenarios'!Q29/'SSP Scenarios'!Q$19 -> 1.6270854 | M13: 2030 | N13: ='SSP Scenarios'!S29/'SSP Scenarios'!S$19 -> 1.4395473 | O13: ='SSP Scenarios'!T29/'SSP Scenarios'!T$19 -> 1.3013616 | P13: ='SSP Scenarios'!U29/'SSP Scenarios'!U$19 -> 1.209819 | Q13: ='SSP Scenarios'!V29/'SSP Scenarios'!V$19 -> 1.5260818
A14: 2040 | B14: ='SSP Scenarios'!I30/'SSP Scenarios'!I$19 -> 1.1068602 | C14: ='SSP Scenarios'!J30/'SSP Scenarios'!J$19 -> 1.1550591 | D14: ='SSP Scenarios'!K30/'SSP Scenarios'!K$19 -> 1.2025974 | E14: ='SSP Scenarios'!L30/'SSP Scenarios'!L$19 -> 1.1125828 | G14: 2040 | H14: ='SSP Scenarios'!N30/'SSP Scenarios'!N$19 -> 2.1921037 | I14: ='SSP Scenarios'!O30/'SSP Scenarios'!O$19 -> 1.8326414 | J14: ='SSP Scenarios'!P30/'SSP Scenarios'!P$19 -> 1.5746407 | K14: ='SSP Scenarios'!Q30/'SSP Scenarios'!Q$19 -> 2.5534838 | M14: 2040 | N14: ='SSP Scenarios'!S30/'SSP Scenarios'!S$19 -> 1.9805688 | O14: ='SSP Scenarios'!T30/'SSP Scenarios'!T$19 -> 1.5866245 | P14: ='SSP Scenarios'!U30/'SSP Scenarios'!U$19 -> 1.3093525 | Q14: ='SSP Scenarios'!V30/'SSP Scenarios'!V$19 -> 2.2951986
A15: 2050 | B15: ='SSP Scenarios'!I31/'SSP Scenarios'!I$19 -> 1.1253298 | C15: ='SSP Scenarios'!J31/'SSP Scenarios'!J$19 -> 1.2049934 | D15: ='SSP Scenarios'!K31/'SSP Scenarios'!K$19 -> 1.2935065 | E15: ='SSP Scenarios'!L31/'SSP Scenarios'!L$19 -> 1.1364238 | G15: 2050 | H15: ='SSP Scenarios'!N31/'SSP Scenarios'!N$19 -> 2.8609311 | I15: ='SSP Scenarios'!O31/'SSP Scenarios'!O$19 -> 2.2755042 | J15: ='SSP Scenarios'!P31/'SSP Scenarios'!P$19 -> 1.7607803 | K15: ='SSP Scenarios'!Q31/'SSP Scenarios'!Q$19 -> 3.578999 | M15: 2050 | N15: ='SSP Scenarios'!S31/'SSP Scenarios'!S$19 -> 2.542436 | O15: ='SSP Scenarios'!T31/'SSP Scenarios'!T$19 -> 1.8883623 | P15: ='SSP Scenarios'!U31/'SSP Scenarios'!U$19 -> 1.3612143 | Q15: ='SSP Scenarios'!V31/'SSP Scenarios'!V$19 -> 3.1494517
... A20: 2100 | B20: ='SSP Scenarios'!I36/'SSP Scenarios'!I$19 -> 0.9182058 | C20: ='SSP Scenarios'!J36/'SSP Scenarios'!J$19 -> 1.1865966 | D20: ='SSP Scenarios'!K36/'SSP Scenarios'!K$19 -> 1.638961 | E20: ='SSP Scenarios'!L36/'SSP Scenarios'!L$19 -> 0.97748344 | G20: 2100 | H20: ='SSP Scenarios'!N36/'SSP Scenarios'!N$19 -> 5.5528383 | I20: ='SSP Scenarios'!O36/'SSP Scenarios'!O$19 -> 5.2583037 | J20: ='SSP Scenarios'!P36/'SSP Scenarios'!P$19 -> 2.6852156 | K20: ='SSP Scenarios'!Q36/'SSP Scenarios'!Q$19 -> 10.117763 | M20: 2100 | N20: ='SSP Scenarios'!S36/'SSP Scenarios'!S$19 -> 6.0477963 | O20: ='SSP Scenarios'!T36/'SSP Scenarios'!T$19 -> 4.4313548 | P20: ='SSP Scenarios'!U36/'SSP Scenarios'!U$19 -> 1.6383904 | Q20: ='SSP Scenarios'!V36/'SSP Scenarios'!V$19 -> 10.351289
A22: Data is based off the SSP Scenarios

Sheet Prediction Results
A1: Expected Damage of Minor Hazards for 2020 | F1: Expected damage of Medium Hazards for 2020 | K1: Expected damage of Major Hazards for 2020 | P1: Expected Property Damages for 2020
A2: Region | B2: Lower | C2: Upper | D2: Average | F2: Region | G2: Lower | H2: Upper | I2: Average | K2: Region | L2: Lower | M2: Upper | N2: Average | P2: Region | Q2: Lower | R2: Upper | S2: Average
A3: 1 | B3: 637301.5 | C3: 818859.4 | D3: 728080.4 | F3: 1 | G3: 4869045.7 | H3: 6607315.8 | I3: 5738180.8 | K3: 1 | L3: 7273781.9 | M3: 18772259 | N3: 13023021 | P3: 1 | Q3: =SUM($B3,$G3,$L3) -> 12780129 | R3: =SUM($C3,$H3,$M3) -> 26198434 | S3: =SUM(D3,I3,N3) -> 19489282
A4: 2 | B4: 957089.4 | C4: 1161032.8 | D4: 1059061.1 | F4: 2 | G4: 6708810.3 | H4: 8793270 | I4: 7751040.1 | K4: 2 | L4: 14309832 | M4: 27353015 | N4: 20831423 | P4: 2 | Q4: =SUM($B4,$G4,$L4) -> 21975731 | R4: =SUM($C4,$H4,$M4) -> 37307318 | S4: =SUM(D4,I4,N4) -> 29641525
A5: 3 | B5: 708746.3 | C5: 1075256.7 | D5: 892001.5 | F5: 3 | G5: 200408.99 | H5: 660668.2 | I5: 430538.62 | K5: 3 | L5: 0 | M5: 515764.13 | N5: 184239.4 | P5: 3 | Q5: =SUM($B5,$G5,$L5) -> 909155.29 | R5: =SUM($C5,$H5,$M5) -> 2251689 | S5: =SUM(D5,I5,N5) -> 1506779.5
A6: 4 | B6: 159923 | C6: 216557.3 | D6: 188240.2 | F6: 4 | G6: 89789.32 | H6: 287276.5 | I6: 188532.92 | K6: 4 | L6: 4214.575 | M6: 33540.63 | N6: 18877.6 | P6: 4 | Q6: =SUM($B6,$G6,$L6) -> 253926.9 | R6: =SUM($C6,$H6,$M6) -> 537374.43 | S6: =SUM(D6,I6,N6) -> 395650.72
A7: 5 | B7: 110462.8 | C7: 157262.9 | D7: 133862.8 | F7: 5 | G7: 54646.88 | H7: 124653.1 | I7: 89650.01 | K7: 5 | L7: 2398.027 | M7: 279181.07 | N7: 140789.5 | P7: 5 | Q7: =SUM($B7,$G7,$L7) -> 167507.71 | R7: =SUM($C7,$H7,$M7) -> 561097.07 | S7: =SUM(D7,I7,N7) -> 364302.31
A8: 6 | B8: 152230.8 | C8: 227168 | D8: 189699.4 | F8: 6 | G8: 206918.18 | H8: 515738.9 | I8: 361328.54 | K8: 6 | L8: 0 | M8: 241269.43 | N8: 107315.4 | P8: 6 | Q8: =SUM($B8,$G8,$L8) -> 359148.98 | R8: =SUM($C8,$H8,$M8) -> 984176.33 | S8: =SUM(D8,I8,N8) -> 658343.34
A10: Expected Frequency of Minor Hazards for 2020 | F10: Expected Frequency of Medium Hazards for 2020 | K10: Expected Frequency of Major Hazards for 2020
A11: Region | B11: Lower | C11: Upper | D11: Average | F11: Region | G11: Lower | H11: Upper | I11: Average | K11: Region | L11: Lower | M11: Upper | N11: Average
A12: 1 | B12: 4.753026 | C12: 5.908667 | D12: 5.330847 | F12: 1 | G12: 2.8920706 | H12: 3.7699461 | I12: 3.3310084 | K12: 1 | L12: 0.63511822 | M12: 1.2511574 | N12: 0.94313779
A13: 2 | B13: 17.033253 | C13: 19.260826 | D13: 18.147039 | F13: 2 | G13: 3.7669012 | H13: 4.7119345 | I13: 4.2394179 | K13: 2 | L13: 0.91317767 | M13: 1.6247976 | N13: 1.2689876
A14: 3 | B14: 21.49466 | C14: 24.505776 | D14: 23.000218 | F14: 3 | G14: 0.18268762 | H14: 0.7503435 | I14: 0.4665156 | K14: 3 | L14: 2.728054e-06 | M14: 0.098897712 | N14: 0.034936917
A15: 4 | B15: 6.274451 | C15: 7.146808 | D15: 6.71063 | F15: 4 | G15: 0.09112506 | H15: 0.2661026 | I15: 0.1786138 | K15: 4 | L15: 0.0003972618 | M15: 0.004657574 | N15: 0.002527418
A16: 5 | B16: 5.146812 | C16: 5.795913 | D16: 5.471363 | F16: 5 | G16: 0.04384714 | H16: 0.1051717 | I16: 0.0745094 | K16: 5 | L16: 0.0021685743 | M16: 0.010526101 | N16: 0.006347338
A17: 6 | B17: 3.310586 | C17: 4.162998 | D17: 3.736792 | F17: 6 | G17: 0.18766701 | H17: 0.3840542 | I17: 0.2858606 | K17: 6 | L17: 0 | M17: 0.020822799 | N17: 0.009616051
A19: Expected Severity of Minor Hazards for 2020 | F19: Expected Severity of Medium Hazards for 2020 | K19: Expected Severity of Major Hazards for 2020
A20: Region | B20: Lower | C20: Upper | D20: Average | F20: Region | G20: Lower | H20: Upper | I20: Average | K20: Region | L20: Lower | M20: Upper | N20: Average
A21: 1 | B21: 115378.04 | C21: 128504.4 | D21: 121941.22 | F21: 1 | G21: 1618092 | H21: 1760330 | I21: 1689211 | K21: 1 | L21: 13474916 | M21: 17761482 | N21: 15618199
A22: 2 | B22: 62700.04 | C22: 71005.1 | D22: 66852.57 | F22: 2 | G22: 1722249 | H22: 1879415 | I22: 1800832 | K22: 2 | L22: 21894899 | M22: 32170861 | N22: 27032880
A23: 3 | B23: 19922.48 | C23: 24836.39 | D23: 22379.44 | F23: 3 | G23: 1151122 | H23: 1372402 | I23: 1261762 | K23: 3 | L23: 6836080 | M23: 7683538 | N23: 7259809
A24: 4 | B24: 22788.4 | C24: 28557.58 | D24: 25672.99 | F24: 4 | G24: 1175298 | H24: 1415357 | I24: 1295328 | K24: 4 | L24: 9431026 | M24: 12029764 | N24: 10730395
A25: 5 | B25: 24317.79 | C25: 30150.38 | D25: 27234.08 | F25: 5 | G25: 1289242 | H25: 1592576 | I25: 1440909 | K25: 5 | L25: 12965270 | M25: 19099580 | N25: 16032425
A26: 6 | B26: 35287.4 | C26: 42355.05 | D26: 38821.23 | F26: 6 | G26: 1223742 | H26: 1473160 | I26: 1348451 | K26: 6 | L26: 8927984 | M26: 10621326 | N26: 9774655

Sheet Prediction Results (Transposed)
A1: Expected Property Damages for 2020 | I1: % of Damage for each hazard severity
A2: {=TRANSPOSE('Prediction Results'!$P$2:$S$8)} -> Region | B2: 1 | C2: 2 | D2: 3 | E2: 4 | F2: 5 | G2: 6 | I2: Region | J2: 1 | K2: 2 | L2: 3 | M2: 4 | N2: 5 | O2: 6
A3: Lower | B3: 12780129 | C3: 21975731 | D3: 909155.29 | E3: 253926.9 | F3: 167507.71 | G3: 359148.98 | I3: Minor | J3: =IF('Involuntary Costs'!$B$4 = "lower", B9/B$3, IF('Involuntary Costs'!$B$4 = "upper", B10/B$4, IF('Involuntary Costs'!$B$4 = "average", B11/B$5, "Invalid"))) -> 0.031256043 | K3: =IF('Involuntary Costs'!$B$4 = "lower", C9/C$3, IF('Involuntary Costs'!$B$4 = "upper", C10/C$4, IF('Involuntary Costs'!$B$4 = "average", C11/C$5, "Invalid"))) -> 0.031120779 | L3: =IF('Involuntary Costs'!$B$4 = "lower", D9/D$3, IF('Involuntary Costs'!$B$4 = "upper", D10/D$4, IF('Involuntary Costs'!$B$4 = "average", D11/D$5, "Invalid"))) -> 0.47753339 | M3: =IF('Involuntary Costs'!$B$4 = "lower", E9/E$3, IF('Involuntary Costs'!$B$4 = "upper", E10/E$4, IF('Involuntary Costs'!$B$4 = "average", E11/E$5, "Invalid"))) -> 0.40299145 | N3: =IF('Involuntary Costs'!$B$4 = "lower", F9/F$3, IF('Involuntary Costs'!$B$4 = "upper", F10/F$4, IF('Involuntary Costs'!$B$4 = "average", F11/F$5, "Invalid"))) -> 0.28027753 | O3: =IF('Involuntary Costs'!$B$4 = "lower", G9/G$3, IF('Involuntary Costs'!$B$4 = "upper", G10/G$4, IF('Involuntary Costs'!$B$4 = "average", G11/G$5, "Invalid"))) -> 0.23082043
A4: Upper | B4: 26198434 | C4: 37307318 | D4: 2251689 | E4: 537374.43 | F4: 561097.07 | G4: 984176.33 | I4: Medium | J4: =IF('Involuntary Costs'!$B$4 = "lower", B15/B$3, IF('Involuntary Costs'!$B$4 = "upper", B16/B$4, IF('Involuntary Costs'!$B$4 = "average", B17/B$5, "Invalid"))) -> 0.2522027 | K4: =IF('Involuntary Costs'!$B$4 = "lower", C15/C$3, IF('Involuntary Costs'!$B$4 = "upper", C16/C$4, IF('Involuntary Costs'!$B$4 = "average", C17/C$5, "Invalid"))) -> 0.23569826 | L4: =IF('Involuntary Costs'!$B$4 = "lower", D15/D$3, IF('Involuntary Costs'!$B$4 = "upper", D16/D$4, IF('Involuntary Costs'!$B$4 = "average", D17/D$5, "Invalid"))) -> 0.29341005 | M4: =IF('Involuntary Costs'!$B$4 = "lower", E15/E$3, IF('Involuntary Costs'!$B$4 = "upper", E16/E$4, IF('Involuntary Costs'!$B$4 = "average", E17/E$5, "Invalid"))) -> 0.5345928 | N4: =IF('Involuntary Costs'!$B$4 = "lower", F15/F$3, IF('Involuntary Costs'!$B$4 = "upper", F16/F$4, IF('Involuntary Costs'!$B$4 = "average", F17/F$5, "Invalid"))) -> 0.2221596 | O4: =IF('Involuntary Costs'!$B$4 = "lower", G15/G$3, IF('Involuntary Costs'!$B$4 = "upper", G16/G$4, IF('Involuntary Costs'!$B$4 = "average", G17/G$5, "Invalid"))) -> 0.52403099
A5: Average | B5: 19489282 | C5: 29641525 | D5: 1506779.5 | E5: 395650.72 | F5: 364302.31 | G5: 658343.34 | I5: Major | J5: =IF('Involuntary Costs'!$B$4 = "lower", B21/B$3, IF('Involuntary Costs'!$B$4 = "upper", B22/B$4, IF('Involuntary Costs'!$B$4 = "average", B23/B$5, "Invalid"))) -> 0.71654126 | K5: =IF('Involuntary Costs'!$B$4 = "lower", C21/C$3, IF('Involuntary Costs'!$B$4 = "upper", C22/C$4, IF('Involuntary Costs'!$B$4 = "average", C23/C$5, "Invalid"))) -> 0.73318096 | L5: =IF('Involuntary Costs'!$B$4 = "lower", D21/D$3, IF('Involuntary Costs'!$B$4 = "upper", D22/D$4, IF('Involuntary Costs'!$B$4 = "average", D23/D$5, "Invalid"))) -> 0.22905655 | M5: =IF('Involuntary Costs'!$B$4 = "lower", E21/E$3, IF('Involuntary Costs'!$B$4 = "upper", E22/E$4, IF('Involuntary Costs'!$B$4 = "average", E23/E$5, "Invalid"))) -> 0.062415754 | N5: =IF('Involuntary Costs'!$B$4 = "lower", F21/F$3, IF('Involuntary Costs'!$B$4 = "upper", F22/F$4, IF('Involuntary Costs'!$B$4 = "average", F23/F$5, "Invalid"))) -> 0.49756287 | O5: =IF('Involuntary Costs'!$B$4 = "lower", G21/G$3, IF('Involuntary Costs'!$B$4 = "upper", G22/G$4, IF('Involuntary Costs'!$B$4 = "average", G23/G$5, "Invalid"))) -> 0.24514858
A7: Expected Minor Hazard Damages for 2020
A8: {=TRANSPOSE('Prediction Results'!$A$2:$D$8)} -> Region | B8: 1 | C8: 2 | D8: 3 | E8: 4 | F8: 5 | G8: 6
A9: Lower | B9: 637301.5 | C9: 957089.4 | D9: 708746.3 | E9: 159923 | F9: 110462.8 | G9: 152230.8
A10: Upper | B10: 818859.4 | C10: 1161032.8 | D10: 1075256.7 | E10: 216557.3 | F10: 157262.9 | G10: 227168
A11: Average | B11: 728080.4 | C11: 1059061.1 | D11: 892001.5 | E11: 188240.2 | F11: 133862.8 | G11: 189699.4
A13: Expected Medium Hazard Damages for 2020
A14: {=TRANSPOSE('Prediction Results'!$F$2:$I$8)} -> Region | B14: 1 | C14: 2 | D14: 3 | E14: 4 | F14: 5 | G14: 6
A15: Lower | B15: 4869045.7 | C15: 6708810.3 | D15: 200408.99 | E15: 89789.32 | F15: 54646.88 | G15: 206918.18
A16: Upper | B16: 6607315.8 | C16: 8793270 | D16: 660668.2 | E16: 287276.5 | F16: 124653.1 | G16: 515738.9
A17: Average | B17: 5738180.8 | C17: 7751040.1 | D17: 430538.62 | E17: 188532.92 | F17: 89650.01 | G17: 361328.54
A19: Expected Major Hazard Damages for 2020
A20: {=TRANSPOSE('Prediction Results'!$K$2:$N$8)} -> Region | B20: 1 | C20: 2 | D20: 3 | E20: 4 | F20: 5 | G20: 6
